Workbook
Name Slicer_Vị_trí: #N/A

Sheet Tong the
A1: DANH SÁCH PHỎNG VẤN
A2: TT | B2: Tham chieu | C2: Họ tên | D2: Vị trí | E2: Chấp thuận | F2: Xem xét | G2: Thời gian đi làm | H2: Lương (thử việc 80%) | I2: Trao đổi với sếp | J2: Ghichú(đội thiết bị,trạm cân,băng tải,cơ điện, sửa chữa,hàn: là28 công/tháng,lái 02 thiết bị;bảo vệ full tháng; vănph, điều độ, quanrly nc 26công; Giờ tăng ca 80K/h,lđ50K; 8h/ca; FC, máy ủi, Liebherr-14tr; Các loại máy 13tr;bánh xích 20t;hàn 11t- tốt12t | K2: Năm sinh | L2: Tình trạng kết hôn | M2: Giới tính | N2: Điện thoại | P2: Vị trí | Q2: Cần tuyển | R2: Đã tuyển | S2: Ghi chú | U2: Vị trí xem xét | W2: Đã tuyển đến thời gian anh Huy chốt
A3: 1 | B3: =D3 -> Lái xe nâng | C3: Võ Tam Lược | D3: Lái xe nâng | E3: OK | G3: 46113 | J3: =P10 -> Lái xe ben | K3: 1989 | L3: x | N3: 0326604512 | P3: Lái cẩu Liebherr | Q3: 6 | R3: =COUNTIF($D$3:$D$183,P3) -> 5 | U3: Lái cẩu Liebherr -x | W3: 7
A4: =A3+1 -> 2 | B4: =D4 -> Tạp vụ | C4: Nguyễn Thị Thu Hà | D4: Tạp vụ | E4: OK | G4: 46113 | H4: 6tr - 8tr/ tháng; thử việc 6tr | K4: 1988 | L4: x | N4: 0916955278 | P4: Lái cẩu bánh xích | Q4: 4 | R4: =COUNTIF($D$3:$D$183,P4) -> 0 | S4: Có 01 bạn đang thử việc ngày 8/4/26 | U4: Lái cẩu bánh xích -x | W4: 1
A5: 3 | B5: =D5 -> Lái xúc lật | C5: Phạm Thanh Bình | D5: Lái xúc lật | E5: OK | G5: 46113 | J5: Có thể lái xe nâng | K5: 1990 | L5: x | N5: 0778584156 | P5: Lái máy ủi | Q5: 12 | R5: =COUNTIF($D$3:$D$183,P5) -> 1 | U5: Lái máy ủi -x | W5: 3
A6: =4 -> 4 | B6: =D6 -> Lái xe nâng | C6: Trình Ánh Dương | D6: Lái xe nâng | E6: OK | G6: 46113 | H6: 12tr, BHXH theo luật | J6: Có thể lái xúc lật | K6: 1987 | L6: X | N6: 0326933225; 0327491211 | P6: Lái xúc lật | Q6: 8 | R6: =COUNTIF($D$3:$D$183,P6) -> 4 | S6: Có bạn Tình đã làm VPCC sẽ chuyển sang làm | U6: Lái xúc lật -x | W6: 2
A7: 5 | B7: =D7 -> Lái máy đào | C7: Phạm Ngọc Hân | D7: Lái máy đào | E7: OK | G7: 46031 | H7: =H6 -> 12tr, BHXH theo luật | J7: Fomer | K7: 1981 | N7: 0974943447 | O7: xz | P7: Lái xe nâng | Q7: 2 | R7: =COUNTIF($D$3:$D$183,P7) -> 2 | U7: Lái xe nâng -x | W7: 2
A8: 6 | B8: =D8 -> Bảo vệ -x | C8: Dương Ngọc Sơn | D8: Bảo vệ -x | F8: X | K8: 1958 | P8: Lái máy đào | Q8: 16 | R8: =COUNTIF($D$3:$D$183,P8) -> 4 | S8: đến ngày 4/3/26: tuyển thêm 02, ngày 22/4 tuyển thêm Cao kỳ (mẫu thuẩn với Trang), vậy còn 02 người (trừ 02 người đã làm từ năm 2025) | U8: Lái máy đào -x | W8: 5
A9: 7 | B9: =D9 -> Kế toán | C9: Nguyễn Thị Thu Hường | D9: Kế toán | E9: OK | G9: 46037 | H9: 8tr/ tháng thử việc | J9: Đào tạo tại Nghi thiết | K9: 2001 | N9: 0799182413 | P9: Thợ vận hành băng tải | Q9: 6 | R9: =COUNTIF($D$3:$D$183,P9) -> 4 | U9: Thợ vận hành băng tải -x | W9: 4
A10: 8 | B10: =D10 -> Trạm cân | C10: Mai Thị Hồng Mận | D10: Trạm cân | E10: OK | G10: 46113 | K10: 1981 | L10: x | N10: 0376664188 | P10: Lái xe ben | Q10: 16 | R10: =COUNTIF($D$3:$D$183,P10) -> 10 | U10: Lái xe ben -x | W10: 10
A11: =A10+1 -> 9 | B11: =D11 -> Trạm cân | C11: Phạm Thị Như | D11: Trạm cân | E11: OK | G11: 46113 | H11: 8tr/tháng; thử việc 1 tháng | J11: Tự bố trí ngày nghỉ đảm bảo | K11: 1993 | L11: x | N11: 0355565275 | P11: Lái xe đầu kéo | Q11: 16 | R11: =COUNTIF($D$3:$D$183,P11) -> 4 | U11: Lái xe đầu kéo -x | W11: 5
A12: 10 | B12: =D12 -> Cơ điện | C12: Trương Thanh Phương | D12: Cơ điện | E12: OK | G12: 46113 | H12: Thử việc 1 tháng | K12: 1991 | N12: 0886608080 | P12: Cơ điện | Q12: 2 | R12: =COUNTIF($D$3:$D$183,P12) -> 2 | U12: Cơ điện -x | W12: 2
A13: =A12+1 -> 11 | B13: =D13 -> Lái máy đào | C13: Phạm Văn Dương | D13: Lái máy đào | E13: OK | G13: 46113 | I13: Cần kế hoạch xin nghỉ trước 20 ngày | J13: Có bằng lái xúc lật | K13: 1990 | N13: 0971999564 | P13: Làm hành chính | Q13: 2 | R13: =COUNTIF($D$3:$D$183,P13) -> 2 | U13: Làm hành chính -x | W13: 2
A14: 12 | B14: =D14 -> Trạm cân | C14: Đinh Thanh Hà | D14: Trạm cân | E14: OK | G14: 46113 | K14: 1983 | N14: 0944654600 | P14: Bảo vệ | Q14: 6 | R14: =COUNTIF($D$3:$D$183,P14) -> 3 | U14: Bảo vệ -x | W14: 4
A15: 13 | B15: =D15 -> Trạm cân | C15: Nguyễn Thị Thu Hằng | D15: Trạm cân | E15: OK | G15: 46082 | H15: 8tr/ tháng; thử việc 6tr | J15: Đào tạo tại Nghi thiết | K15: 2003 | N15: 0799106337 | P15: Kế toán | Q15: 2 | R15: =COUNTIF($D$3:$D$183,P15) -> 2 | U15: Kế toán -x | W15: 2
A16: 14 | B16: =D16 -> Trạm cân | C16: Lê Thị Kiều Trang | D16: Trạm cân | E16: OK | G16: 46082 | H16: =H15 -> 8tr/ tháng; thử việc 6tr | J16: Đào tạo tại Nghi thiết | K16: =K15 -> 2003 | N16: 0948252943 | P16: Kinh doanh | Q16: 1 | R16: =COUNTIF($D$3:$D$183,P16) -> 2 | U16: Kinh doanh -x | W16: 2
A17: 15 | B17: =D17 -> Bảo vệ -x | C17: Lê Viết Thanh | D17: Bảo vệ -x | J17: 12h/ca | K17: 1973 | N17: 0985596469 | P17: Trạm cân | Q17: 6 | R17: =COUNTIF($D$3:$D$183,P17) -> 6 | U17: Trạm cân -x | W17: 6
A18: 16 | B18: =D18 -> Lái xe đầu kéo -x | C18: Phan Thanh Dũng | D18: Lái xe đầu kéo -x | J18: Có thể lái cẩu | K18: 1986 | N18: 0865493444 | P18: Phụ trách kho bãi | Q18: 1 | R18: =COUNTIF($D$3:$D$183,P18) -> 1 | U18: Phụ trách kho bãi -x | W18: 1
A19: 17 | B19: =D19 -> Tạp vụ | C19: Hoàng Thị Tính | D19: Tạp vụ | E19: OK | G19: 46113 | J19: Quen A. Sơn -Đại diện | K19: 1992 | N19: 0965719908 | P19: Lao động phổ thông | Q19: 55 | R19: =COUNTIF($D$3:$D$183,P19) -> 31 | U19: Lao động phổ thông -x | W19: 19
A20: 18 | B20: =D20 -> Tạp vụ | C20: Nguyễn Thị Bé | D20: Tạp vụ | E20: OK | G20: 46113 | J20: =J19 -> Quen A. Sơn -Đại diện | K20: 1987 | N20: 0911073787 | P20: Tạp vụ | Q20: 5 | R20: =COUNTIF($D$3:$D$183,P20) -> 5 | U20: Tạp vụ -x | W20: 5
A21: =A20+1 -> 19 | B21: =D21 -> Kế toán | C21: Từ Nữ Kiều Trinh | D21: Kế toán | E21: OK | G21: 46082 | H21: Đại học, Tiếng Anh tốt; BHXH theo thực nhận | J21: Đào tạo tại Nghi thiết | K21: 1998 | N21: 0961544089 | P21: Quản lý cơ giới | Q21: 1 | R21: =COUNTIF($D$3:$D$183,P21) -> 1 | U21: Quản lý cơ giới -x | W21: 1
A22: 20 | B22: =D22 -> Lao động phổ thông | C22: Đinh Thị Thúy Hằng | D22: Lao động phổ thông | E22: OK | G22: 46113 | K22: 1991 | N22: 0976916154 | P22: Điều độ | R22: =COUNTIF($D$3:$D$183,P22) -> 3 | U22: Điều độ -x | W22: 3
A23: 21 | B23: =D23 -> Tạp vụ | C23: Võ Thị Nhường | D23: Tạp vụ | E23: OK | G23: 46113 | H23: 6-8tr/ tháng | K23: 1992 | N23: 0392037554 | P23: Phòng Y Tế | Q23: 1 | R23: =COUNTIF($D$3:$D$183,P23) -> 1 | U23: Sửa chữa -x | W23: 1
A24: 22 | B24: =D24 -> Tạp vụ | C24: Đặng Thị Tiết | D24: Tạp vụ | E24: OK | G24: 46113 | H24: =H23 -> 6-8tr/ tháng | K24: 1989 | N24: 0363420442 | P24: Tổ trưởng nhân công | Q24: 1 | R24: =COUNTIF($D$3:$D$183,P24) -> 1 | U24: Thợ hàn -x | W24: 1
A25: =A24+1 -> 23 | B25: =D25 -> Kế toán -x | C25: Trần Trúc Quỳnh | D25: Kế toán -x | F25: X | J25: Đã làm thuế | K25: 2003 | N25: 0812624770 | P25: Thợ hàn | Q25: 2 | R25: =COUNTIF($D$3:$D$183,P25) -> 2
A26: =A25+1 -> 24 | B26: =D26 -> Lao động phổ thông | C26: Nguyễn Lê Khắc Ánh | D26: Lao động phổ thông | E26: OK | G26: 46113 | H26: 350K/công; Vận hành băng tải dăm 400-450K/công; xếp cali | J26: Có thể vận hành băng tải; xếp cali | N26: 0799161327 | P26: Sửa chữa | Q26: 2 | R26: =COUNTIF($D$3:$D$183,P26) -> 0 | W26: 0
A27: =A26+1 -> 25 | B27: =D27 -> Lao động phổ thông | C27: Nguyễn Văn Thái | D27: Lao động phổ thông | E27: OK | G27: 46113 | H27: =H26 -> 350K/công; Vận hành băng tải dăm 400-450K/công; xếp cali | J27: =J26 -> Có thể vận hành băng tải; xếp cali | N27: 0944455516 | P27: Tổng | Q27: =SUM(Q3:Q26) -> 173 | R27: =SUM(R3:R26) -> 96 | W27: =SUM(W3:W26) -> 88
A28: =A27+1 -> 26 | B28: =D28 -> Lao động phổ thông | C28: Trần Văn Hoài | D28: Lao động phổ thông | E28: OK | G28: 46113 | H28: =H27 -> 350K/công; Vận hành băng tải dăm 400-450K/công; xếp cali | J28: =J27 -> Có thể vận hành băng tải; xếp cali | N28: 0773369659
A29: =A28+1 -> 27 | B29: =D29 -> Kinh doanh | C29: Nguyễn Vũ Duy | D29: Kinh doanh | E29: OK | G29: 46082 | J29: Đào tạo tại Nghi thiết | K29: 2003 | N29: 0916118042
A30: 28 | B30: =D30 -> 0
A31: =A30+1 -> 29 | B31: =D31 -> Lao động phổ thông | C31: Hà Thị Định | D31: Lao động phổ thông | E31: OK | G31: 46113 | M31: Nữ | N31: 0773371784
A32: =A31+1 -> 30 | B32: =D32 -> Lao động phổ thông | C32: Bùi Thị Hằng | D32: Lao động phổ thông | E32: OK | G32: 46113 | M32: Nữ | N32: 0705283539 | O32: xz
A33: =A32+1 -> 31 | B33: =D33 -> Cơ điện | C33: Hồ Tiến Lực | D33: Cơ điện | E33: OK | G33: 46113 | K33: 1984 | N33: 0978764897
A34: =A33+1 -> 32 | B34: =D34 -> Lái xe đầu kéo | C34: Trịnh Minh Quý | D34: Lái xe đầu kéo | E34: OK | G34: 46113 | K34: 1989 | N34: 0986365377
A35: =A34+1 -> 33 | B35: =D35 -> Lái xe ben | C35: Lưu Văn Khánh | D35: Lái xe ben | E35: OK | G35: 46113 | K35: 1984 | N35: 0363329273
A36: =A35+1 -> 34 | B36: =D36 -> Làm hành chính | C36: Nguyễn Văn Tuyến | D36: Làm hành chính | E36: OK | G36: 46113 | J36: Cơ bản làm hành chính | K36: 1977 | N36: 0961778150
A37: =A36+1 -> 35 | B37: =D37 -> Làm hành chính | C37: Lê Thị Vân Anh | D37: Làm hành chính | E37: OK | G37: 46037 | K37: 2003 | N37: 0965951621
A38: =A37+1 -> 36 | B38: =D38 -> Tạp vụ -x | C38: Lê Thị Hoài | D38: Tạp vụ -x | F38: X | K38: 1993 | N38: 0395757327
A39: =A38+1 -> 37 | B39: =D39 -> Lái xe ben | C39: Nguyễn Văn Hậu | D39: Lái xe ben | E39: OK | H39: 12tr | J39: Em Hội, chưa phỏng vấn | N39: 0857116333
A40: =A39+1 -> 38 | B40: =D40 -> Trạm cân | C40: Nguyễn Thị Ngọc Lan | D40: Trạm cân | E40: OK | G40: 46113 | J40: 26ca/ tháng | K40: 2003 | N40: 0944267623
...

Sheet DS đào tạo
B1: DANH SÁCH ĐI ĐÀO TẠO
A2: Tham chiếu | B2: STT | C2: Họ tên | D2: Vị trí | E2: Thời gian đi làm | F2: Năm sinh | G2: Điện thoại
A3: 7 | B3: 1 | C3: =VLOOKUP($A3, 'Tong the'!$A$3:$N$150,3,0) -> Nguyễn Thị Thu Hường | D3: =VLOOKUP($A3, 'Tong the'!$A$3:$N$150,4,0) -> Kế toán | E3: =VLOOKUP($A3, 'Tong the'!$A$3:$N$150,7,0) -> 46037 | F3: =VLOOKUP($A3, 'Tong the'!$A$3:$N$150,11,0) -> 2001 | G3: =VLOOKUP($A3, 'Tong the'!$A$3:$N$150,14,0) -> 0799182413
A4: 13 | B4: =B3+1 -> 2 | C4: =VLOOKUP($A4, 'Tong the'!$A$3:$N$150,3,0) -> Nguyễn Thị Thu Hằng | D4: =VLOOKUP($A4, 'Tong the'!$A$3:$N$150,4,0) -> Trạm cân | E4: =VLOOKUP($A4, 'Tong the'!$A$3:$N$150,7,0) -> 46082 | F4: =VLOOKUP($A4, 'Tong the'!$A$3:$N$150,11,0) -> 2003 | G4: =VLOOKUP($A4, 'Tong the'!$A$3:$N$150,14,0) -> 0799106337
A5: 14 | B5: =B4+1 -> 3 | C5: =VLOOKUP($A5, 'Tong the'!$A$3:$N$150,3,0) -> Lê Thị Kiều Trang | D5: =VLOOKUP($A5, 'Tong the'!$A$3:$N$150,4,0) -> Trạm cân | E5: =VLOOKUP($A5, 'Tong the'!$A$3:$N$150,7,0) -> 46082 | F5: =VLOOKUP($A5, 'Tong the'!$A$3:$N$150,11,0) -> 2003 | G5: =VLOOKUP($A5, 'Tong the'!$A$3:$N$150,14,0) -> 0948252943
A6: 19 | B6: =B5+1 -> 4 | C6: =VLOOKUP($A6, 'Tong the'!$A$3:$N$150,3,0) -> Từ Nữ Kiều Trinh | D6: =VLOOKUP($A6, 'Tong the'!$A$3:$N$150,4,0) -> Kế toán | E6: =VLOOKUP($A6, 'Tong the'!$A$3:$N$150,7,0) -> 46082 | F6: =VLOOKUP($A6, 'Tong the'!$A$3:$N$150,11,0) -> 1998 | G6: =VLOOKUP($A6, 'Tong the'!$A$3:$N$150,14,0) -> 0961544089
A7: 27 | B7: =B6+1 -> 5 | C7: =VLOOKUP($A7, 'Tong the'!$A$3:$N$150,3,0) -> Nguyễn Vũ Duy | D7: =VLOOKUP($A7, 'Tong the'!$A$3:$N$150,4,0) -> Kinh doanh | E7: =VLOOKUP($A7, 'Tong the'!$A$3:$N$150,7,0) -> 46082 | F7: =VLOOKUP($A7, 'Tong the'!$A$3:$N$150,11,0) -> 2003 | G7: =VLOOKUP($A7, 'Tong the'!$A$3:$N$150,14,0) -> 0916118042
A8: 41 | B8: =B7+1 -> 6 | C8: =VLOOKUP($A8, 'Tong the'!$A$3:$N$150,3,0) -> Đặng Yến Quang | D8: =VLOOKUP($A8, 'Tong the'!$A$3:$N$150,4,0) -> Lái cẩu Liebherr | E8: =VLOOKUP($A8, 'Tong the'!$A$3:$N$150,7,0) -> 46040 | F8: =VLOOKUP($A8, 'Tong the'!$A$3:$N$150,11,0) -> 1986 | G8: =VLOOKUP($A8, 'Tong the'!$A$3:$N$150,14,0) -> 0823509379
A9: 48 | B9: =B8+1 -> 7 | C9: =VLOOKUP($A9, 'Tong the'!$A$3:$N$150,3,0) -> Lưu Đức Tình | D9: =VLOOKUP($A9, 'Tong the'!$A$3:$N$150,4,0) -> Tổ trưởng nhân công | E9: =VLOOKUP($A9, 'Tong the'!$A$3:$N$150,7,0) -> 46082 | F9: =VLOOKUP($A9, 'Tong the'!$A$3:$N$150,11,0) -> 1997 | G9: =VLOOKUP($A9, 'Tong the'!$A$3:$N$150,14,0) -> 0372346667
A10: 49 | B10: =B9+1 -> 8 | C10: =VLOOKUP($A10, 'Tong the'!$A$3:$N$150,3,0) -> Lưu Thị Nghĩa | D10: =VLOOKUP($A10, 'Tong the'!$A$3:$N$150,4,0) -> Kinh doanh | E10: =VLOOKUP($A10, 'Tong the'!$A$3:$N$150,7,0) -> 46082 | F10: =VLOOKUP($A10, 'Tong the'!$A$3:$N$150,11,0) -> 1999 | G10: =VLOOKUP($A10, 'Tong the'!$A$3:$N$150,14,0) -> 0829423293
A11: 59 | B11: =B10+1 -> 9 | C11: =VLOOKUP($A11, 'Tong the'!$A$3:$N$150,3,0) -> Trần Ngọc Huy | D11: =VLOOKUP($A11, 'Tong the'!$A$3:$N$150,4,0) -> Thợ vận hành băng tải | E11: =VLOOKUP($A11, 'Tong the'!$A$3:$N$150,7,0) -> 46082 | F11: =VLOOKUP($A11, 'Tong the'!$A$3:$N$150,11,0) -> 1999 | G11: =VLOOKUP($A11, 'Tong the'!$A$3:$N$150,14,0) -> 0963593585
A12: 35 | B12: =B11+1 -> 10 | C12: =VLOOKUP($A12, 'Tong the'!$A$3:$N$150,3,0) -> Lê Thị Vân Anh | D12: =VLOOKUP($A12, 'Tong the'!$A$3:$N$150,4,0) -> Làm hành chính | E12: =VLOOKUP($A12, 'Tong the'!$A$3:$N$150,7,0) -> 46037 | F12: =VLOOKUP($A12, 'Tong the'!$A$3:$N$150,11,0) -> 2003 | G12: =VLOOKUP($A12, 'Tong the'!$A$3:$N$150,14,0) -> 0965951621

Sheet Sheet1 (2)
B1: THEO DÕI ỨNG VIÊN VÀO LÀM VIỆC TẠI CẢNG THQT HÒN LA
B2: TT | C2: Vị trí việc làm | D2: Số lượng người cần tuyển | E2: Số lượng chờ/ đã phỏng vấn | F2: Số lượng đã nhận | G2: Số lượng còn lại | H2: Tên ứng viên đã nhận | I2: Ghi chú | J2: Ghi chú/ Lưu ý
B3: 1 | C3: Lái cẩu Liebherr | D3: 6 | E3: 3 | F3: ='Tong the'!R3 -> 5 | G3: =D3-F3 -> 1 | I3: Ngày làm 8h/ ca; ngoài giờ: 80K/tiếng | J3: Ngày làm 8h/ ca; ngoài giờ: 80K/tiếng
B4: 2 | C4: Lái cẩu bánh xích | D4: 4 | E4: 0 | F4: ='Tong the'!R4 -> 0 | G4: =D4-F4 -> 4
B5: 3 | C5: Lái máy ủi | D5: 12 | E5: 0 | F5: ='Tong the'!R5 -> 1 | G5: =D5-F5 -> 11
B6: 4 | C6: Lái xúc lật | D6: 8 | E6: 0 | F6: ='Tong the'!R6 -> 4 | G6: =D6-F6 -> 4
B7: 5 | C7: Lái xe nâng | D7: 2 | E7: 0 | F7: ='Tong the'!R7 -> 2 | G7: =D7-F7 -> 0
B8: 6 | C8: Lái máy đào | D8: 16 | E8: 1 | F8: ='Tong the'!R8 -> 4 | G8: =D8-F8 -> 12
B9: 7 | C9: Thợ vận hành băng tải | D9: 6 | E9: 0 | F9: ='Tong the'!R9 -> 4 | G9: =D9-F9 -> 2
B10: 8 | C10: Lái xe ben | D10: 16 | E10: 2 | F10: ='Tong the'!R10 -> 10 | G10: =D10-F10 -> 6 | J10: Tuấn giới thiệu 02 ứng viên bà con
B11: 9 | C11: Lái xe đầu kéo | D11: 16 | E11: 4 | F11: ='Tong the'!R11 -> 4 | G11: =D11-F11 -> 12
B12: 10 | C12: Cơ điện | D12: 2 | E12: 1 | F12: ='Tong the'!R12 -> 2 | G12: =D12-F12 -> 0 | H12: Phương,
B13: 11 | C13: Làm hành chính | D13: 2 | E13: 1 | F13: ='Tong the'!R13 -> 2 | G13: =D13-F13 -> 0 | H13: V.Anh, Tuyến | J13: Em Bình (theo dõi lương, công, chế độ người lao động) + Em tố Hiếu (hồ sơ, sắp xếp tiếp khách, soạn công văn)
B14: 12 | C14: Bảo vệ | D14: 6 | E14: 3 | F14: ='Tong the'!R14 -> 3 | G14: =D14-F14 -> 3 | J14: 01 người - Chú L Tuấn + 01 Cậu A Trường Hải Quan Cha Lo
B15: 13 | C15: Kế toán | D15: 2 | E15: 3 | F15: ='Tong the'!R15 -> 2 | G15: =D15-F15 -> 0 | H15: Hường | J15: Cháu anh Hệ Hải Quan (mới ra trường)+ Cháu A Tùng Gd CV Hà Tĩnh + Người quen A. Hiền PCT
B16: 14 | C16: Kinh doanh | D16: 1 | E16: 1 | F16: ='Tong the'!R16 -> 2 | G16: =D16-F16 -> -1 | H16: Lưu Nghĩa | J16: Cháu Lưu Tuấn
B17: 15 | C17: Trạm cân | D17: 6 | E17: 3 | F17: ='Tong the'!R17 -> 6 | G17: =D17-F17 -> 0 | H17: Trang,T.Hằng, H.Mận, N.Lan | J17: Cháu A Tùng + Em Bình + Chị Trang Nguyên Lợi+ Lan (FPT, tiếng Anh tốt)
B18: 16 | C18: Phụ trách kho bãi | D18: 1 | E18: 1 | F18: ='Tong the'!R18 -> 1 | G18: =D18-F18 -> 0 | H18: Hùng | J18: Em bạn Lưu Tuấn
B19: 17 | C19: Lao động phổ thông | D19: 55 | E19: 1 | F19: ='Tong the'!R19 -> 31 | G19: =D19-F19 -> 24 | H19: Tình | J19: Cháu L Tuấn (tổ trưởng nhân công)
B20: 18 | C20: Tạp vụ | D20: 5 | E20: 5 | F20: ='Tong the'!R20 -> 5 | G20: =D20-F20 -> 0
B21: 19 | C21: Sửa chữa | D21: 2 | E21: 0 | F21: ='Tong the'!R26 -> 0 | G21: =D21-F21 -> 2 | J21: Sữa chữa các loại máy; quản lý thiết bị'
D22: =SUM(D3:D21) -> 168 | E22: =SUM(E3:E21) -> 29 | F22: =SUM(F3:F21) -> 88
