Workbook
Name DM_ma_loai_PA: 'Phương án'!$A$3:$A$30
Name dm_quocgia: 'DM Quốc tịch'!$B$2:$B$241
Name dmhuyen: Huyen!$C:$C
Name dmtinh: Tinhcu!$B$2:$B$65
Name dmtinh: Tinh!$B$2:$B$36
Name dmxa: Xa!$D:$D
Name gioitinh: 'Giới tính'!$A$1:$A$2
Name huong_BHYT: 'DM Mức hưởng BHYT'!$A$2:$A$6
Name huongbhyt: 'DM Mức hưởng BHYT'!$A$2:$A$6
Name loaipa: 'Loại PA'!$B$2:$B$6
Name Loc_trung_huyen: Huyen!$D$2:$D$3322
Name Loc_trung_xa: Xa!$E$2:$E$10039
Name Ma_PA: 'Phương án'!$B$3:$B$30
Name ma_quocgia: 'DM Quốc tịch'!$A:$A
Name ma_tinhxa: Xa!$A:$A
Name mabenhvien: KCB!$B:$B
Name madantoc: 'Dân tộc'!$A$2:$A$57
Name madmhuyen: Huyen!$B:$B
Name magt: GioiTinh!$A$2:$A$3
Name magioitinh: GioiTinh!$A:$A
Name mahuong: 'DM Mức hưởng BHYT'!$A$2:$A$6
Name mahuyen: Huyen!$B$2:$B$3322
Name mahuyen_xa: Xa!$B:$B
Name mahuyenxa: Xa!$B:$B
Name maloaipa: 'Loại PA'!$A$2:$A$6
Name mamoiquanhe: 'Mối quan hệ'!$A$2:$A$24
Name maquocgia: 'DM Quốc tịch'!$A$2:$A$241
Name maquoctich: 'DM Quốc tịch'!$A$47:$A$241
Name matinh: Tinhcu!$A$2:$A$65
Name matinh: Tinh!$A$2:$A$36
Name matinh_huyen: Huyen!$A:$A
Name matinhbenhvien: KCB!$A:$A
Name Matinhcu: Tinhcu!$A$2:$A$64
Name matinhhuyen: Huyen!$A:$A
Name maxa: Xa!$C$2:$C$10039
Name moiquanhe: 'Mối quan hệ'!$B$2:$B$24
Name muchuong: 'DM Mức hưởng BHYT'!$1:$1048576
Name muchuongbhxh: 'DM Mức hưởng BHYT'!$B$2:$B$6
Name Ten_PA: 'Phương án'!$C$3:$C$30
Name ten_tinh: Tinhcu!$B$2:$B$66
Name ten_tinh: Tinh!$B$2:$B$37
Name tenbenhvien: KCB!$C:$C
Name tendantoc: 'Dân tộc'!$B$2:$B$57
Name tenphuongan: 'Phương án'!$C$3:$C$30
Name tenquocgia: 'DM Quốc tịch'!$B:$B
Name tentinh: Tinhcu!$B$2:$B$65
Name tentinh: Tinh!$B$2:$B$36
Name Tentinhcu: Tinhcu!$B$2:$B$64
Name tengioitinh: GioiTinh!$B:$B
Name true_false: Sheet1!$A$1:$A$2
Name Ma_Tinh: '[1]Danh mục'!$G$3:$G$65

Sheet DuLieu
A1: DANH SÁCH LAO ĐỘNG THAM GIA BHXH, BHYT, BHTN, BHTNLĐ, BNN (Mẫu D02-LT TK1) Các ô chữ màu đỏ là các thông tin bắt buộc | BA1: Chọn xuất TK1-TS đối với các phương án TM, TD, TC, TH | CC1: NLĐ chưa có mã số BHXH nhập thông tin phụ lục hộ gia đình
A2: STT | B2: Họ và tên | C2: Mã số BHXH | D2: Loại phương án | E2: Mã loại PA | F2: Loại ngày sinh | G2: Ngày Sinh | H2: Giới tính | I2: Số CMND/ CCCD/Hộ chiếu | J2: Cấp bậc, chức vụ, chức danh nghề | K2: Phòng ban làm việc | L2: Nơi Làm Việc | M2: Tiền đồng | P2: Hệ số lương | T2: Phương án điều chỉnh | U2: Mã PA | V2: Tháng/ năm bắt đầu | W2: Tháng/ năm kết thúc | X2: Nghỉ ốm đau/Thai sản/không lương | Z2: Ghi chú | AA2: Số sổ BHXH | AB2: Mức hưởng BHYT | AC2: Tỷ lệ đóng (%) | AD2: Mã vùng sinh sống | AE2: Mã vùng lương tối thiểu | AF2: Có giảm chết | AG2: Ngày chết | AH2: Tính lãi | AI2: Nhóm vị trí việc làm | AJ2: Ngày bắt đầu giữ vị trí | AK2: Ngày kết thúc giữ vị trí | AL2: Hợp đồng lao động | AO2: Ngành nghề nặng nhọc, độc hại | AQ2: Hợp đồng lao động | AS2: Quốc tịch | AT2: Mã QT | AU2: Dân tộc | AV2: Mã DT | AW2: Tỉnh ngân hàng | AX2: Mã tỉnh | AY2: Ngân hàng | AZ2: Mã ngân hàng | BA2: Điện thoại liên hệ | BB2: Email liên hệ | BC2: Thông tin đăng ký khai sinh | BH2: Thông tin địa chỉ nhận hồ sơ | BM2: Nơi đăng ký khám chữa bệnh ban đầu | BQ2: Đăng ký nhận sổ và thẻ | BR2: Địa chỉ nhận Sổ, thẻ | BW2: Mức tiền đóng | BX2: Phương thức đóng | BY2: Nội dung thay đổi | BZ2: Hồ sơ kèm theo | CA2: Họ tên người giám hộ | CB2: Mã số hộ gia đình | CC2: Thông tin chủ hộ | CT2: Phụ lục gia đình
M3: Mức lương | N3: Phụ cấp lương | O3: Các khoản bổ sung | P3: Hệ số | Q3: Phụ cấp CV | R3: Phụ cấp TNVK (%) | S3: Phụ cấp TN nghề (%) | X3: Từ ngày | Y3: Đến ngày | AL3: Loại HĐLĐ | AM3: Hiệu lực từ ngày | AN3: Hiệu lực đến ngày | AO3: Ngày bắt đầu | AP3: Ngày kết thúc | AQ3: Số | AR3: Ngày ký | BC3: Tỉnh / Thành phố | BD3: Mã Tỉnh | BE3: Phường/ Xã | BF3: Mã xã | BG3: Địa chỉ khai sinh | BH3: Tỉnh / Thành phố | BI3: Mã Tỉnh | BJ3: Phường/ Xã | BK3: Mã xã | BL3: Địa chỉ nhận hồ sơ | BM3: Tỉnh nơi KCB | BN3: Mã tỉnh | BO3: Nơi đăng ký KCB | BP3: Mã BV | BR3: Tỉnh / Thành phố | BS3: Mã Tỉnh | BT3: Phường/ Xã | BU3: Mã Xã | BV3: Địa chỉ nhận Sổ thẻ | CC3: Họ Tên chủ hộ | CD3: Số CMND/ CCCD/Hộ chiếu | CE3: Điện thoại | CF3: Loại giấy tờ | CG3: Số giấy tờ | CH3: Tỉnh / Thành phố | CI3: Mã Tỉnh | CJ3: Phường/ Xã | CK3: Mã xã | CL3: Tổ/ Thôn/ Xóm | CM3: Địa chỉ hộ khẩu | CN3: Tỉnh / Thành phố thường trú | CO3: Mã Tỉnh | CP3: Phường/ Xã thường trú | CQ3: Mã xã | CR3: Địa chỉ thường trú | CS3: Mã số hộ gia đình | CT3: Họ và tên | CU3: Mã số BHXH | CV3: Loại ngày sinh | CW3: Ngày sinh | CX3: Giới tính | CY3: Quốc tịch | CZ3: Mã Quốc tịch | DA3: Dân tộc | DB3: Mã Dân tộc | DC3: Số CMND | DD3: Mối quan hệ với chủ hộ | DE3: Mã MQH | DF3: Tỉnh / Thành phố | DG3: Mã Tỉnh | DH3: Phường/ Xã | DI3: Mã xã | DJ3: Địa chỉ khai sinh | DK3: Người tham gia | DL3: Ghi chú
A4: STT | B4: HoTen | C4: MaSoBhxh | E4: LoaiHoSo | F4: ChiCoNamSinh | G4: NgaySinh | H4: GioiTinh | I4: Cmnd | J4: ChucVu | K4: MaPhongBan | L4: NoiLamViec | M4: TienLuong | N4: PhuCapLuong | O4: PhuCapBoSung | P4: Heso | Q4: PhuCapChucVu | R4: PhuCapThamNienVuotKhung | S4: PhuCapThamNienNghe | U4: PhuongAnId | V4: TuThang | W4: DenThang | X4: Tungay | Y4: Denngay | Z4: GhiChu | AA4: SoSoBHXH | AB4: MucHuongBaoHiemYTe | AC4: TyleDong | AD4: MaVungSinhSong | AE4: VungLuongToiThieuId | AF4: CoGiamChet | AG4: NgayChet | AH4: TinhLai | AI4: NhomChucVu | AJ4: TuNgayChucVu | AK4: DenNgayChucVu | AL4: LoaiHDLD | AM4: TuNgayHDLD | AN4: DenNgayHDLD | AO4: TuNgayDocHai | AP4: DenNgayDocHai | AQ4: SoHDLD | AR4: NgayKy | AT4: QuocTichId | AV4: DanTocId | AW4: TenTinh_NH | AX4: MaTinh_NH | AY4: TenNganHang | AZ4: MaNganHang | BA4: DienThoaiLienHe | BB4: Email | BD4: KhaiSinhTinhId | BF4: KhaiSinhXaId | BG4: DiaChiKhaiSinh | BI4: NoiNhanTinhId | BK4: NoiNhanXaId | BL4: NoiNhanDiaChiChiTiet | BN4: BenhVienTinhId | BP4: BenhVienId | BQ4: DangKyNhanSoThe | BS4: TinhNhanBanGiayId | BU4: XaNhanBanGiayId | BV4: DiaChiNhanBanGiay | BW4: MucDongTk01 | BX4: PhuongThucTk1 | BY4: NoiDungThayDoi | BZ4: HoSoKemTheo | CA4: HoTenNguoiGiamHo | CB4: MaHoGiaDinh | CC4: HoTenChuHo | CD4: CmndChuHo | CE4: DienThoaiChuHo | CF4: LoaiGiayToId | CG4: SoGiayTo | CI4: ChuHoTinhId | CK4: ChuHoXaId | CL4: ChuHoThonId | CM4: DiaChiHoKhau | CN4: ThuonTruChuHoTinh | CO4: TinhThuongTruChuHoId | CP4: ThuongTruChuHoXa | CQ4: XaThuongTruChuHoId | CR4: DiaChiThuongTruChuHo | CS4: MaSoHoGiaDinh | CT4: HoTen_TV | CU4: MaSoBhxh_TV | CV4: ChiCoNamSinh_TV | CW4: NgaySinh_TV | CX4: GioiTinh_TV | CZ4: QuocTich_TV | DB4: DanToc_TV | DC4: Cmnd_TV | DE4: MoiQuanHe_TV | DG4: KhaiSinhTinhId_TV | DI4: KhaiSinhXaId_TV | DJ4: DiaChiKhaiSinh_TV | DK4: LaNguoiThamGia_TV | DL4: GhiChu_TV | DM4: KEY_D02TS_TK01595_01082020
E5: =IF(ISBLANK(D5),"",INDEX(maloaipa,MATCH(D5,loaipa,0))) | U5: =IF(ISBLANK(T5),"",INDEX(Ma_PA,MATCH(T5,'Phương án'!$C$3:C31,0))) | AT5: =IF(ISBLANK(AS5),"",INDEX(maquocgia,MATCH(AS5,dm_quocgia,0))) | AV5: =IF(ISBLANK(AU5),"",INDEX(madantoc,MATCH(AU5,tendantoc,0))) | AX5: {=IFERROR(INDEX(Tinh!A:A,MATCH(TRIM(AW5),Tinh!B:B,0)),"")} | AZ5: {=IFERROR(INDEX('Ngân Hàng'!B:B,MATCH(AY5,'Ngân Hàng'!C:C,0)),"")} | BD5: =IF(ISBLANK(BC5),"",INDEX(matinh,MATCH(BC5,ten_tinh,0))) | BF5: =IF(ISBLANK(BE5),"",INDEX(mahuyen,MATCH(CONCATENATE(BD5,"-",BE5),Loc_trung_huyen,0))) | BI5: =IF(ISBLANK(BH5),"",INDEX(matinh,MATCH(BH5,ten_tinh,0))) | BK5: =IF(ISBLANK(BJ5),"",INDEX(mahuyen,MATCH(CONCATENATE(BI5,"-",BJ5),Loc_trung_huyen,0))) | BN5: =IF(ISBLANK(BM5),"",INDEX(matinh,MATCH(BM5,ten_tinh,0))) | BP5: {=IF(ISBLANK(BO5),"",INDEX(mabenhvien,MATCH(BO5&BN5,tenbenhvien&matinhbenhvien,0)))} | BS5: =IF(ISBLANK(BR5),"",INDEX(matinh,MATCH(BR5,ten_tinh,0))) | BU5: =IF(ISBLANK(BT5),"",INDEX(mahuyen,MATCH(CONCATENATE(BS5,"-",BT5),Loc_trung_huyen,0))) | CI5: =IF(ISBLANK(CH5),"",INDEX(matinh,MATCH(CH5,ten_tinh,0))) | CK5: =IF(ISBLANK(CJ5),"",INDEX(mahuyen,MATCH(CONCATENATE(CI5,"-",CJ5),Loc_trung_huyen,0))) | CO5: =IF(ISBLANK(CN5),"",INDEX(matinh,MATCH(CN5,ten_tinh,0))) | CQ5: =IF(ISBLANK(CP5),"",INDEX(mahuyen,MATCH(CONCATENATE(CO5,"-",CP5),Loc_trung_huyen,0))) | CZ5: =IF(ISBLANK(CY5),"",INDEX(maquocgia,MATCH(CY5,dm_quocgia,0))) | DB5: =IF(ISBLANK(DA5),"",INDEX(madantoc,MATCH(DA5,tendantoc,0))) | DE5: =IF(ISBLANK(DD5),"",INDEX(mamoiquanhe,MATCH(DD5,moiquanhe,0))) | DG5: =IF(ISBLANK(DF5),"",INDEX(matinh,MATCH(DF5,ten_tinh,0))) | DI5: =IF(ISBLANK(DH5),"",INDEX(mahuyen,MATCH(CONCATENATE(DG5,"-",DH5),Loc_trung_huyen,0)))
E6: =IF(ISBLANK(D6),"",INDEX(maloaipa,MATCH(D6,loaipa,0))) | U6: =IF(ISBLANK(T6),"",INDEX(Ma_PA,MATCH(T6,'Phương án'!$C$3:C32,0))) | AT6: =IF(ISBLANK(AS6),"",INDEX(maquocgia,MATCH(AS6,dm_quocgia,0))) | AV6: =IF(ISBLANK(AU6),"",INDEX(madantoc,MATCH(AU6,tendantoc,0))) | AX6: {=IFERROR(INDEX(Tinh!A:A,MATCH(TRIM(AW6),Tinh!B:B,0)),"")} | AZ6: {=IFERROR(INDEX('Ngân Hàng'!B:B,MATCH(AY6,'Ngân Hàng'!C:C,0)),"")} | BD6: =IF(ISBLANK(BC6),"",INDEX(matinh,MATCH(BC6,ten_tinh,0))) | BF6: =IF(ISBLANK(BE6),"",INDEX(mahuyen,MATCH(CONCATENATE(BD6,"-",BE6),Loc_trung_huyen,0))) | BI6: =IF(ISBLANK(BH6),"",INDEX(matinh,MATCH(BH6,ten_tinh,0))) | BK6: =IF(ISBLANK(BJ6),"",INDEX(mahuyen,MATCH(CONCATENATE(BI6,"-",BJ6),Loc_trung_huyen,0))) | BN6: =IF(ISBLANK(BM6),"",INDEX(matinh,MATCH(BM6,ten_tinh,0))) | BP6: {=IF(ISBLANK(BO6),"",INDEX(mabenhvien,MATCH(BO6&BN6,tenbenhvien&matinhbenhvien,0)))} | BS6: =IF(ISBLANK(BR6),"",INDEX(matinh,MATCH(BR6,ten_tinh,0))) | BU6: =IF(ISBLANK(BT6),"",INDEX(mahuyen,MATCH(CONCATENATE(BS6,"-",BT6),Loc_trung_huyen,0))) | CI6: =IF(ISBLANK(CH6),"",INDEX(matinh,MATCH(CH6,ten_tinh,0))) | CK6: =IF(ISBLANK(CJ6),"",INDEX(mahuyen,MATCH(CONCATENATE(CI6,"-",CJ6),Loc_trung_huyen,0))) | CO6: =IF(ISBLANK(CN6),"",INDEX(matinh,MATCH(CN6,ten_tinh,0))) | CQ6: =IF(ISBLANK(CP6),"",INDEX(mahuyen,MATCH(CONCATENATE(CO6,"-",CP6),Loc_trung_huyen,0))) | CZ6: =IF(ISBLANK(CY6),"",INDEX(maquocgia,MATCH(CY6,dm_quocgia,0))) | DB6: =IF(ISBLANK(DA6),"",INDEX(madantoc,MATCH(DA6,tendantoc,0))) | DE6: =IF(ISBLANK(DD6),"",INDEX(mamoiquanhe,MATCH(DD6,moiquanhe,0))) | DG6: =IF(ISBLANK(DF6),"",INDEX(matinh,MATCH(DF6,ten_tinh,0))) | DI6: =IF(ISBLANK(DH6),"",INDEX(mahuyen,MATCH(CONCATENATE(DG6,"-",DH6),Loc_trung_huyen,0)))
E7: =IF(ISBLANK(D7),"",INDEX(maloaipa,MATCH(D7,loaipa,0))) | U7: =IF(ISBLANK(T7),"",INDEX(Ma_PA,MATCH(T7,'Phương án'!$C$3:C33,0))) | AT7: =IF(ISBLANK(AS7),"",INDEX(maquocgia,MATCH(AS7,dm_quocgia,0))) | AV7: =IF(ISBLANK(AU7),"",INDEX(madantoc,MATCH(AU7,tendantoc,0))) | AX7: {=IFERROR(INDEX(Tinh!A:A,MATCH(TRIM(AW7),Tinh!B:B,0)),"")} | AZ7: {=IFERROR(INDEX('Ngân Hàng'!B:B,MATCH(AY7,'Ngân Hàng'!C:C,0)),"")} | BD7: =IF(ISBLANK(BC7),"",INDEX(matinh,MATCH(BC7,ten_tinh,0))) | BF7: =IF(ISBLANK(BE7),"",INDEX(mahuyen,MATCH(CONCATENATE(BD7,"-",BE7),Loc_trung_huyen,0))) | BI7: =IF(ISBLANK(BH7),"",INDEX(matinh,MATCH(BH7,ten_tinh,0))) | BK7: =IF(ISBLANK(BJ7),"",INDEX(mahuyen,MATCH(CONCATENATE(BI7,"-",BJ7),Loc_trung_huyen,0))) | BN7: =IF(ISBLANK(BM7),"",INDEX(matinh,MATCH(BM7,ten_tinh,0))) | BP7: {=IF(ISBLANK(BO7),"",INDEX(mabenhvien,MATCH(BO7&BN7,tenbenhvien&matinhbenhvien,0)))} | BS7: =IF(ISBLANK(BR7),"",INDEX(matinh,MATCH(BR7,ten_tinh,0))) | BU7: =IF(ISBLANK(BT7),"",INDEX(mahuyen,MATCH(CONCATENATE(BS7,"-",BT7),Loc_trung_huyen,0))) | CI7: =IF(ISBLANK(CH7),"",INDEX(matinh,MATCH(CH7,ten_tinh,0))) | CK7: =IF(ISBLANK(CJ7),"",INDEX(mahuyen,MATCH(CONCATENATE(CI7,"-",CJ7),Loc_trung_huyen,0))) | CO7: =IF(ISBLANK(CN7),"",INDEX(matinh,MATCH(CN7,ten_tinh,0))) | CQ7: =IF(ISBLANK(CP7),"",INDEX(mahuyen,MATCH(CONCATENATE(CO7,"-",CP7),Loc_trung_huyen,0))) | CZ7: =IF(ISBLANK(CY7),"",INDEX(maquocgia,MATCH(CY7,dm_quocgia,0))) | DB7: =IF(ISBLANK(DA7),"",INDEX(madantoc,MATCH(DA7,tendantoc,0))) | DE7: =IF(ISBLANK(DD7),"",INDEX(mamoiquanhe,MATCH(DD7,moiquanhe,0))) | DG7: =IF(ISBLANK(DF7),"",INDEX(matinh,MATCH(DF7,ten_tinh,0))) | DI7: =IF(ISBLANK(DH7),"",INDEX(mahuyen,MATCH(CONCATENATE(DG7,"-",DH7),Loc_trung_huyen,0)))
E8: =IF(ISBLANK(D8),"",INDEX(maloaipa,MATCH(D8,loaipa,0))) | U8: =IF(ISBLANK(T8),"",INDEX(Ma_PA,MATCH(T8,'Phương án'!$C$3:C34,0))) | AT8: =IF(ISBLANK(AS8),"",INDEX(maquocgia,MATCH(AS8,dm_quocgia,0))) | AV8: =IF(ISBLANK(AU8),"",INDEX(madantoc,MATCH(AU8,tendantoc,0))) | AX8: {=IFERROR(INDEX(Tinh!A:A,MATCH(TRIM(AW8),Tinh!B:B,0)),"")} | AZ8: {=IFERROR(INDEX('Ngân Hàng'!B:B,MATCH(AY8,'Ngân Hàng'!C:C,0)),"")} | BD8: =IF(ISBLANK(BC8),"",INDEX(matinh,MATCH(BC8,ten_tinh,0))) | BF8: =IF(ISBLANK(BE8),"",INDEX(mahuyen,MATCH(CONCATENATE(BD8,"-",BE8),Loc_trung_huyen,0))) | BI8: =IF(ISBLANK(BH8),"",INDEX(matinh,MATCH(BH8,ten_tinh,0))) | BK8: =IF(ISBLANK(BJ8),"",INDEX(mahuyen,MATCH(CONCATENATE(BI8,"-",BJ8),Loc_trung_huyen,0))) | BN8: =IF(ISBLANK(BM8),"",INDEX(matinh,MATCH(BM8,ten_tinh,0))) | BP8: {=IF(ISBLANK(BO8),"",INDEX(mabenhvien,MATCH(BO8&BN8,tenbenhvien&matinhbenhvien,0)))} | BS8: =IF(ISBLANK(BR8),"",INDEX(matinh,MATCH(BR8,ten_tinh,0))) | BU8: =IF(ISBLANK(BT8),"",INDEX(mahuyen,MATCH(CONCATENATE(BS8,"-",BT8),Loc_trung_huyen,0))) | CI8: =IF(ISBLANK(CH8),"",INDEX(matinh,MATCH(CH8,ten_tinh,0))) | CK8: =IF(ISBLANK(CJ8),"",INDEX(mahuyen,MATCH(CONCATENATE(CI8,"-",CJ8),Loc_trung_huyen,0))) | CO8: =IF(ISBLANK(CN8),"",INDEX(matinh,MATCH(CN8,ten_tinh,0))) | CQ8: =IF(ISBLANK(CP8),"",INDEX(mahuyen,MATCH(CONCATENATE(CO8,"-",CP8),Loc_trung_huyen,0))) | CZ8: =IF(ISBLANK(CY8),"",INDEX(maquocgia,MATCH(CY8,dm_quocgia,0))) | DB8: =IF(ISBLANK(DA8),"",INDEX(madantoc,MATCH(DA8,tendantoc,0))) | DE8: =IF(ISBLANK(DD8),"",INDEX(mamoiquanhe,MATCH(DD8,moiquanhe,0))) | DG8: =IF(ISBLANK(DF8),"",INDEX(matinh,MATCH(DF8,ten_tinh,0))) | DI8: =IF(ISBLANK(DH8),"",INDEX(mahuyen,MATCH(CONCATENATE(DG8,"-",DH8),Loc_trung_huyen,0)))
E9: =IF(ISBLANK(D9),"",INDEX(maloaipa,MATCH(D9,loaipa,0))) | U9: =IF(ISBLANK(T9),"",INDEX(Ma_PA,MATCH(T9,'Phương án'!$C$3:C35,0))) | AT9: =IF(ISBLANK(AS9),"",INDEX(maquocgia,MATCH(AS9,dm_quocgia,0))) | AV9: =IF(ISBLANK(AU9),"",INDEX(madantoc,MATCH(AU9,tendantoc,0))) | AX9: {=IFERROR(INDEX(Tinh!A:A,MATCH(TRIM(AW9),Tinh!B:B,0)),"")} | AZ9: {=IFERROR(INDEX('Ngân Hàng'!B:B,MATCH(AY9,'Ngân Hàng'!C:C,0)),"")} | BD9: =IF(ISBLANK(BC9),"",INDEX(matinh,MATCH(BC9,ten_tinh,0))) | BF9: =IF(ISBLANK(BE9),"",INDEX(mahuyen,MATCH(CONCATENATE(BD9,"-",BE9),Loc_trung_huyen,0))) | BI9: =IF(ISBLANK(BH9),"",INDEX(matinh,MATCH(BH9,ten_tinh,0))) | BK9: =IF(ISBLANK(BJ9),"",INDEX(mahuyen,MATCH(CONCATENATE(BI9,"-",BJ9),Loc_trung_huyen,0))) | BN9: =IF(ISBLANK(BM9),"",INDEX(matinh,MATCH(BM9,ten_tinh,0))) | BP9: {=IF(ISBLANK(BO9),"",INDEX(mabenhvien,MATCH(BO9&BN9,tenbenhvien&matinhbenhvien,0)))} | BS9: =IF(ISBLANK(BR9),"",INDEX(matinh,MATCH(BR9,ten_tinh,0))) | BU9: =IF(ISBLANK(BT9),"",INDEX(mahuyen,MATCH(CONCATENATE(BS9,"-",BT9),Loc_trung_huyen,0))) | CI9: =IF(ISBLANK(CH9),"",INDEX(matinh,MATCH(CH9,ten_tinh,0))) | CK9: =IF(ISBLANK(CJ9),"",INDEX(mahuyen,MATCH(CONCATENATE(CI9,"-",CJ9),Loc_trung_huyen,0))) | CO9: =IF(ISBLANK(CN9),"",INDEX(matinh,MATCH(CN9,ten_tinh,0))) | CQ9: =IF(ISBLANK(CP9),"",INDEX(mahuyen,MATCH(CONCATENATE(CO9,"-",CP9),Loc_trung_huyen,0))) | CZ9: =IF(ISBLANK(CY9),"",INDEX(maquocgia,MATCH(CY9,dm_quocgia,0))) | DB9: =IF(ISBLANK(DA9),"",INDEX(madantoc,MATCH(DA9,tendantoc,0))) | DE9: =IF(ISBLANK(DD9),"",INDEX(mamoiquanhe,MATCH(DD9,moiquanhe,0))) | DG9: =IF(ISBLANK(DF9),"",INDEX(matinh,MATCH(DF9,ten_tinh,0))) | DI9: =IF(ISBLANK(DH9),"",INDEX(mahuyen,MATCH(CONCATENATE(DG9,"-",DH9),Loc_trung_huyen,0)))
E10: =IF(ISBLANK(D10),"",INDEX(maloaipa,MATCH(D10,loaipa,0))) | U10: =IF(ISBLANK(T10),"",INDEX(Ma_PA,MATCH(T10,'Phương án'!$C$3:C36,0))) | AT10: =IF(ISBLANK(AS10),"",INDEX(maquocgia,MATCH(AS10,dm_quocgia,0))) | AV10: =IF(ISBLANK(AU10),"",INDEX(madantoc,MATCH(AU10,tendantoc,0))) | AX10: {=IFERROR(INDEX(Tinh!A:A,MATCH(TRIM(AW10),Tinh!B:B,0)),"")} | AZ10: {=IFERROR(INDEX('Ngân Hàng'!B:B,MATCH(AY10,'Ngân Hàng'!C:C,0)),"")} | BD10: =IF(ISBLANK(BC10),"",INDEX(matinh,MATCH(BC10,ten_tinh,0))) | BF10: =IF(ISBLANK(BE10),"",INDEX(mahuyen,MATCH(CONCATENATE(BD10,"-",BE10),Loc_trung_huyen,0))) | BI10: =IF(ISBLANK(BH10),"",INDEX(matinh,MATCH(BH10,ten_tinh,0))) | BK10: =IF(ISBLANK(BJ10),"",INDEX(mahuyen,MATCH(CONCATENATE(BI10,"-",BJ10),Loc_trung_huyen,0))) | BN10: =IF(ISBLANK(BM10),"",INDEX(matinh,MATCH(BM10,ten_tinh,0))) | BP10: {=IF(ISBLANK(BO10),"",INDEX(mabenhvien,MATCH(BO10&BN10,tenbenhvien&matinhbenhvien,0)))} | BS10: =IF(ISBLANK(BR10),"",INDEX(matinh,MATCH(BR10,ten_tinh,0))) | BU10: =IF(ISBLANK(BT10),"",INDEX(mahuyen,MATCH(CONCATENATE(BS10,"-",BT10),Loc_trung_huyen,0))) | CI10: =IF(ISBLANK(CH10),"",INDEX(matinh,MATCH(CH10,ten_tinh,0))) | CK10: =IF(ISBLANK(CJ10),"",INDEX(mahuyen,MATCH(CONCATENATE(CI10,"-",CJ10),Loc_trung_huyen,0))) | CO10: =IF(ISBLANK(CN10),"",INDEX(matinh,MATCH(CN10,ten_tinh,0))) | CQ10: =IF(ISBLANK(CP10),"",INDEX(mahuyen,MATCH(CONCATENATE(CO10,"-",CP10),Loc_trung_huyen,0))) | CZ10: =IF(ISBLANK(CY10),"",INDEX(maquocgia,MATCH(CY10,dm_quocgia,0))) | DB10: =IF(ISBLANK(DA10),"",INDEX(madantoc,MATCH(DA10,tendantoc,0))) | DE10: =IF(ISBLANK(DD10),"",INDEX(mamoiquanhe,MATCH(DD10,moiquanhe,0))) | DG10: =IF(ISBLANK(DF10),"",INDEX(matinh,MATCH(DF10,ten_tinh,0))) | DI10: =IF(ISBLANK(DH10),"",INDEX(mahuyen,MATCH(CONCATENATE(DG10,"-",DH10),Loc_trung_huyen,0)))
E11: =IF(ISBLANK(D11),"",INDEX(maloaipa,MATCH(D11,loaipa,0))) | U11: =IF(ISBLANK(T11),"",INDEX(Ma_PA,MATCH(T11,'Phương án'!$C$3:C37,0))) | AT11: =IF(ISBLANK(AS11),"",INDEX(maquocgia,MATCH(AS11,dm_quocgia,0))) | AV11: =IF(ISBLANK(AU11),"",INDEX(madantoc,MATCH(AU11,tendantoc,0))) | AX11: {=IFERROR(INDEX(Tinh!A:A,MATCH(TRIM(AW11),Tinh!B:B,0)),"")} | AZ11: {=IFERROR(INDEX('Ngân Hàng'!B:B,MATCH(AY11,'Ngân Hàng'!C:C,0)),"")} | BD11: =IF(ISBLANK(BC11),"",INDEX(matinh,MATCH(BC11,ten_tinh,0))) | BF11: =IF(ISBLANK(BE11),"",INDEX(mahuyen,MATCH(CONCATENATE(BD11,"-",BE11),Loc_trung_huyen,0))) | BI11: =IF(ISBLANK(BH11),"",INDEX(matinh,MATCH(BH11,ten_tinh,0))) | BK11: =IF(ISBLANK(BJ11),"",INDEX(mahuyen,MATCH(CONCATENATE(BI11,"-",BJ11),Loc_trung_huyen,0))) | BN11: =IF(ISBLANK(BM11),"",INDEX(matinh,MATCH(BM11,ten_tinh,0))) | BP11: {=IF(ISBLANK(BO11),"",INDEX(mabenhvien,MATCH(BO11&BN11,tenbenhvien&matinhbenhvien,0)))} | BS11: =IF(ISBLANK(BR11),"",INDEX(matinh,MATCH(BR11,ten_tinh,0))) | BU11: =IF(ISBLANK(BT11),"",INDEX(mahuyen,MATCH(CONCATENATE(BS11,"-",BT11),Loc_trung_huyen,0))) | CI11: =IF(ISBLANK(CH11),"",INDEX(matinh,MATCH(CH11,ten_tinh,0))) | CK11: =IF(ISBLANK(CJ11),"",INDEX(mahuyen,MATCH(CONCATENATE(CI11,"-",CJ11),Loc_trung_huyen,0))) | CO11: =IF(ISBLANK(CN11),"",INDEX(matinh,MATCH(CN11,ten_tinh,0))) | CQ11: =IF(ISBLANK(CP11),"",INDEX(mahuyen,MATCH(CONCATENATE(CO11,"-",CP11),Loc_trung_huyen,0))) | CZ11: =IF(ISBLANK(CY11),"",INDEX(maquocgia,MATCH(CY11,dm_quocgia,0))) | DB11: =IF(ISBLANK(DA11),"",INDEX(madantoc,MATCH(DA11,tendantoc,0))) | DE11: =IF(ISBLANK(DD11),"",INDEX(mamoiquanhe,MATCH(DD11,moiquanhe,0))) | DG11: =IF(ISBLANK(DF11),"",INDEX(matinh,MATCH(DF11,ten_tinh,0))) | DI11: =IF(ISBLANK(DH11),"",INDEX(mahuyen,MATCH(CONCATENATE(DG11,"-",DH11),Loc_trung_huyen,0)))
E12: =IF(ISBLANK(D12),"",INDEX(maloaipa,MATCH(D12,loaipa,0))) | U12: =IF(ISBLANK(T12),"",INDEX(Ma_PA,MATCH(T12,'Phương án'!$C$3:C38,0))) | AT12: =IF(ISBLANK(AS12),"",INDEX(maquocgia,MATCH(AS12,dm_quocgia,0))) | AV12: =IF(ISBLANK(AU12),"",INDEX(madantoc,MATCH(AU12,tendantoc,0))) | AX12: {=IFERROR(INDEX(Tinh!A:A,MATCH(TRIM(AW12),Tinh!B:B,0)),"")} | AZ12: {=IFERROR(INDEX('Ngân Hàng'!B:B,MATCH(AY12,'Ngân Hàng'!C:C,0)),"")} | BD12: =IF(ISBLANK(BC12),"",INDEX(matinh,MATCH(BC12,ten_tinh,0))) | BF12: =IF(ISBLANK(BE12),"",INDEX(mahuyen,MATCH(CONCATENATE(BD12,"-",BE12),Loc_trung_huyen,0))) | BI12: =IF(ISBLANK(BH12),"",INDEX(matinh,MATCH(BH12,ten_tinh,0))) | BK12: =IF(ISBLANK(BJ12),"",INDEX(mahuyen,MATCH(CONCATENATE(BI12,"-",BJ12),Loc_trung_huyen,0))) | BN12: =IF(ISBLANK(BM12),"",INDEX(matinh,MATCH(BM12,ten_tinh,0))) | BP12: {=IF(ISBLANK(BO12),"",INDEX(mabenhvien,MATCH(BO12&BN12,tenbenhvien&matinhbenhvien,0)))} | BS12: =IF(ISBLANK(BR12),"",INDEX(matinh,MATCH(BR12,ten_tinh,0))) | BU12: =IF(ISBLANK(BT12),"",INDEX(mahuyen,MATCH(CONCATENATE(BS12,"-",BT12),Loc_trung_huyen,0))) | CI12: =IF(ISBLANK(CH12),"",INDEX(matinh,MATCH(CH12,ten_tinh,0))) | CK12: =IF(ISBLANK(CJ12),"",INDEX(mahuyen,MATCH(CONCATENATE(CI12,"-",CJ12),Loc_trung_huyen,0))) | CO12: =IF(ISBLANK(CN12),"",INDEX(matinh,MATCH(CN12,ten_tinh,0))) | CQ12: =IF(ISBLANK(CP12),"",INDEX(mahuyen,MATCH(CONCATENATE(CO12,"-",CP12),Loc_trung_huyen,0))) | CZ12: =IF(ISBLANK(CY12),"",INDEX(maquocgia,MATCH(CY12,dm_quocgia,0))) | DB12: =IF(ISBLANK(DA12),"",INDEX(madantoc,MATCH(DA12,tendantoc,0))) | DE12: =IF(ISBLANK(DD12),"",INDEX(mamoiquanhe,MATCH(DD12,moiquanhe,0))) | DG12: =IF(ISBLANK(DF12),"",INDEX(matinh,MATCH(DF12,ten_tinh,0))) | DI12: =IF(ISBLANK(DH12),"",INDEX(mahuyen,MATCH(CONCATENATE(DG12,"-",DH12),Loc_trung_huyen,0)))
E13: =IF(ISBLANK(D13),"",INDEX(maloaipa,MATCH(D13,loaipa,0))) | U13: =IF(ISBLANK(T13),"",INDEX(Ma_PA,MATCH(T13,'Phương án'!$C$3:C39,0))) | AT13: =IF(ISBLANK(AS13),"",INDEX(maquocgia,MATCH(AS13,dm_quocgia,0))) | AV13: =IF(ISBLANK(AU13),"",INDEX(madantoc,MATCH(AU13,tendantoc,0))) | AX13: {=IFERROR(INDEX(Tinh!A:A,MATCH(TRIM(AW13),Tinh!B:B,0)),"")} | AZ13: {=IFERROR(INDEX('Ngân Hàng'!B:B,MATCH(AY13,'Ngân Hàng'!C:C,0)),"")} | BD13: =IF(ISBLANK(BC13),"",INDEX(matinh,MATCH(BC13,ten_tinh,0))) | BF13: =IF(ISBLANK(BE13),"",INDEX(mahuyen,MATCH(CONCATENATE(BD13,"-",BE13),Loc_trung_huyen,0))) | BI13: =IF(ISBLANK(BH13),"",INDEX(matinh,MATCH(BH13,ten_tinh,0))) | BK13: =IF(ISBLANK(BJ13),"",INDEX(mahuyen,MATCH(CONCATENATE(BI13,"-",BJ13),Loc_trung_huyen,0))) | BN13: =IF(ISBLANK(BM13),"",INDEX(matinh,MATCH(BM13,ten_tinh,0))) | BP13: {=IF(ISBLANK(BO13),"",INDEX(mabenhvien,MATCH(BO13&BN13,tenbenhvien&matinhbenhvien,0)))} | BS13: =IF(ISBLANK(BR13),"",INDEX(matinh,MATCH(BR13,ten_tinh,0))) | BU13: =IF(ISBLANK(BT13),"",INDEX(mahuyen,MATCH(CONCATENATE(BS13,"-",BT13),Loc_trung_huyen,0))) | CI13: =IF(ISBLANK(CH13),"",INDEX(matinh,MATCH(CH13,ten_tinh,0))) | CK13: =IF(ISBLANK(CJ13),"",INDEX(mahuyen,MATCH(CONCATENATE(CI13,"-",CJ13),Loc_trung_huyen,0))) | CO13: =IF(ISBLANK(CN13),"",INDEX(matinh,MATCH(CN13,ten_tinh,0))) | CQ13: =IF(ISBLANK(CP13),"",INDEX(mahuyen,MATCH(CONCATENATE(CO13,"-",CP13),Loc_trung_huyen,0))) | CZ13: =IF(ISBLANK(CY13),"",INDEX(maquocgia,MATCH(CY13,dm_quocgia,0))) | DB13: =IF(ISBLANK(DA13),"",INDEX(madantoc,MATCH(DA13,tendantoc,0))) | DE13: =IF(ISBLANK(DD13),"",INDEX(mamoiquanhe,MATCH(DD13,moiquanhe,0))) | DG13: =IF(ISBLANK(DF13),"",INDEX(matinh,MATCH(DF13,ten_tinh,0))) | DI13: =IF(ISBLANK(DH13),"",INDEX(mahuyen,MATCH(CONCATENATE(DG13,"-",DH13),Loc_trung_huyen,0)))
E14: =IF(ISBLANK(D14),"",INDEX(maloaipa,MATCH(D14,loaipa,0))) | U14: =IF(ISBLANK(T14),"",INDEX(Ma_PA,MATCH(T14,'Phương án'!$C$3:C40,0))) | AT14: =IF(ISBLANK(AS14),"",INDEX(maquocgia,MATCH(AS14,dm_quocgia,0))) | AV14: =IF(ISBLANK(AU14),"",INDEX(madantoc,MATCH(AU14,tendantoc,0))) | AX14: {=IFERROR(INDEX(Tinh!A:A,MATCH(TRIM(AW14),Tinh!B:B,0)),"")} | AZ14: {=IFERROR(INDEX('Ngân Hàng'!B:B,MATCH(AY14,'Ngân Hàng'!C:C,0)),"")} | BD14: =IF(ISBLANK(BC14),"",INDEX(matinh,MATCH(BC14,ten_tinh,0))) | BF14: =IF(ISBLANK(BE14),"",INDEX(mahuyen,MATCH(CONCATENATE(BD14,"-",BE14),Loc_trung_huyen,0))) | BI14: =IF(ISBLANK(BH14),"",INDEX(matinh,MATCH(BH14,ten_tinh,0))) | BK14: =IF(ISBLANK(BJ14),"",INDEX(mahuyen,MATCH(CONCATENATE(BI14,"-",BJ14),Loc_trung_huyen,0))) | BN14: =IF(ISBLANK(BM14),"",INDEX(matinh,MATCH(BM14,ten_tinh,0))) | BP14: {=IF(ISBLANK(BO14),"",INDEX(mabenhvien,MATCH(BO14&BN14,tenbenhvien&matinhbenhvien,0)))} | BS14: =IF(ISBLANK(BR14),"",INDEX(matinh,MATCH(BR14,ten_tinh,0))) | BU14: =IF(ISBLANK(BT14),"",INDEX(mahuyen,MATCH(CONCATENATE(BS14,"-",BT14),Loc_trung_huyen,0))) | CI14: =IF(ISBLANK(CH14),"",INDEX(matinh,MATCH(CH14,ten_tinh,0))) | CK14: =IF(ISBLANK(CJ14),"",INDEX(mahuyen,MATCH(CONCATENATE(CI14,"-",CJ14),Loc_trung_huyen,0))) | CO14: =IF(ISBLANK(CN14),"",INDEX(matinh,MATCH(CN14,ten_tinh,0))) | CQ14: =IF(ISBLANK(CP14),"",INDEX(mahuyen,MATCH(CONCATENATE(CO14,"-",CP14),Loc_trung_huyen,0))) | CZ14: =IF(ISBLANK(CY14),"",INDEX(maquocgia,MATCH(CY14,dm_quocgia,0))) | DB14: =IF(ISBLANK(DA14),"",INDEX(madantoc,MATCH(DA14,tendantoc,0))) | DE14: =IF(ISBLANK(DD14),"",INDEX(mamoiquanhe,MATCH(DD14,moiquanhe,0))) | DG14: =IF(ISBLANK(DF14),"",INDEX(matinh,MATCH(DF14,ten_tinh,0))) | DI14: =IF(ISBLANK(DH14),"",INDEX(mahuyen,MATCH(CONCATENATE(DG14,"-",DH14),Loc_trung_huyen,0)))
E15: =IF(ISBLANK(D15),"",INDEX(maloaipa,MATCH(D15,loaipa,0))) | U15: =IF(ISBLANK(T15),"",INDEX(Ma_PA,MATCH(T15,'Phương án'!$C$3:C41,0))) | AT15: =IF(ISBLANK(AS15),"",INDEX(maquocgia,MATCH(AS15,dm_quocgia,0))) | AV15: =IF(ISBLANK(AU15),"",INDEX(madantoc,MATCH(AU15,tendantoc,0))) | AX15: {=IFERROR(INDEX(Tinh!A:A,MATCH(TRIM(AW15),Tinh!B:B,0)),"")} | AZ15: {=IFERROR(INDEX('Ngân Hàng'!B:B,MATCH(AY15,'Ngân Hàng'!C:C,0)),"")} | BD15: =IF(ISBLANK(BC15),"",INDEX(matinh,MATCH(BC15,ten_tinh,0))) | BF15: =IF(ISBLANK(BE15),"",INDEX(mahuyen,MATCH(CONCATENATE(BD15,"-",BE15),Loc_trung_huyen,0))) | BI15: =IF(ISBLANK(BH15),"",INDEX(matinh,MATCH(BH15,ten_tinh,0))) | BK15: =IF(ISBLANK(BJ15),"",INDEX(mahuyen,MATCH(CONCATENATE(BI15,"-",BJ15),Loc_trung_huyen,0))) | BN15: =IF(ISBLANK(BM15),"",INDEX(matinh,MATCH(BM15,ten_tinh,0))) | BP15: {=IF(ISBLANK(BO15),"",INDEX(mabenhvien,MATCH(BO15&BN15,tenbenhvien&matinhbenhvien,0)))} | BS15: =IF(ISBLANK(BR15),"",INDEX(matinh,MATCH(BR15,ten_tinh,0))) | BU15: =IF(ISBLANK(BT15),"",INDEX(mahuyen,MATCH(CONCATENATE(BS15,"-",BT15),Loc_trung_huyen,0))) | CI15: =IF(ISBLANK(CH15),"",INDEX(matinh,MATCH(CH15,ten_tinh,0))) | CK15: =IF(ISBLANK(CJ15),"",INDEX(mahuyen,MATCH(CONCATENATE(CI15,"-",CJ15),Loc_trung_huyen,0))) | CO15: =IF(ISBLANK(CN15),"",INDEX(matinh,MATCH(CN15,ten_tinh,0))) | CQ15: =IF(ISBLANK(CP15),"",INDEX(mahuyen,MATCH(CONCATENATE(CO15,"-",CP15),Loc_trung_huyen,0))) | CZ15: =IF(ISBLANK(CY15),"",INDEX(maquocgia,MATCH(CY15,dm_quocgia,0))) | DB15: =IF(ISBLANK(DA15),"",INDEX(madantoc,MATCH(DA15,tendantoc,0))) | DE15: =IF(ISBLANK(DD15),"",INDEX(mamoiquanhe,MATCH(DD15,moiquanhe,0))) | DG15: =IF(ISBLANK(DF15),"",INDEX(matinh,MATCH(DF15,ten_tinh,0))) | DI15: =IF(ISBLANK(DH15),"",INDEX(mahuyen,MATCH(CONCATENATE(DG15,"-",DH15),Loc_trung_huyen,0)))
E16: =IF(ISBLANK(D16),"",INDEX(maloaipa,MATCH(D16,loaipa,0))) | U16: =IF(ISBLANK(T16),"",INDEX(Ma_PA,MATCH(T16,'Phương án'!$C$3:C42,0))) | AT16: =IF(ISBLANK(AS16),"",INDEX(maquocgia,MATCH(AS16,dm_quocgia,0))) | AV16: =IF(ISBLANK(AU16),"",INDEX(madantoc,MATCH(AU16,tendantoc,0))) | AX16: {=IFERROR(INDEX(Tinh!A:A,MATCH(TRIM(AW16),Tinh!B:B,0)),"")} | AZ16: {=IFERROR(INDEX('Ngân Hàng'!B:B,MATCH(AY16,'Ngân Hàng'!C:C,0)),"")} | BD16: =IF(ISBLANK(BC16),"",INDEX(matinh,MATCH(BC16,ten_tinh,0))) | BF16: =IF(ISBLANK(BE16),"",INDEX(mahuyen,MATCH(CONCATENATE(BD16,"-",BE16),Loc_trung_huyen,0))) | BI16: =IF(ISBLANK(BH16),"",INDEX(matinh,MATCH(BH16,ten_tinh,0))) | BK16: =IF(ISBLANK(BJ16),"",INDEX(mahuyen,MATCH(CONCATENATE(BI16,"-",BJ16),Loc_trung_huyen,0))) | BN16: =IF(ISBLANK(BM16),"",INDEX(matinh,MATCH(BM16,ten_tinh,0))) | BP16: {=IF(ISBLANK(BO16),"",INDEX(mabenhvien,MATCH(BO16&BN16,tenbenhvien&matinhbenhvien,0)))} | BS16: =IF(ISBLANK(BR16),"",INDEX(matinh,MATCH(BR16,ten_tinh,0))) | BU16: =IF(ISBLANK(BT16),"",INDEX(mahuyen,MATCH(CONCATENATE(BS16,"-",BT16),Loc_trung_huyen,0))) | CI16: =IF(ISBLANK(CH16),"",INDEX(matinh,MATCH(CH16,ten_tinh,0))) | CK16: =IF(ISBLANK(CJ16),"",INDEX(mahuyen,MATCH(CONCATENATE(CI16,"-",CJ16),Loc_trung_huyen,0))) | CO16: =IF(ISBLANK(CN16),"",INDEX(matinh,MATCH(CN16,ten_tinh,0))) | CQ16: =IF(ISBLANK(CP16),"",INDEX(mahuyen,MATCH(CONCATENATE(CO16,"-",CP16),Loc_trung_huyen,0))) | CZ16: =IF(ISBLANK(CY16),"",INDEX(maquocgia,MATCH(CY16,dm_quocgia,0))) | DB16: =IF(ISBLANK(DA16),"",INDEX(madantoc,MATCH(DA16,tendantoc,0))) | DE16: =IF(ISBLANK(DD16),"",INDEX(mamoiquanhe,MATCH(DD16,moiquanhe,0))) | DG16: =IF(ISBLANK(DF16),"",INDEX(matinh,MATCH(DF16,ten_tinh,0))) | DI16: =IF(ISBLANK(DH16),"",INDEX(mahuyen,MATCH(CONCATENATE(DG16,"-",DH16),Loc_trung_huyen,0)))
... E516: =IF(ISBLANK(D516),"",INDEX(maloaipa,MATCH(D516,loaipa,0))) | U516: =IF(ISBLANK(T516),"",INDEX(Ma_PA,MATCH(T516,'Phương án'!$C$3:C542,0))) | AT516: =IF(ISBLANK(AS516),"",INDEX(maquocgia,MATCH(AS516,dm_quocgia,0))) | AV516: =IF(ISBLANK(AU516),"",INDEX(madantoc,MATCH(AU516,tendantoc,0))) | AX516: {=IFERROR(INDEX(Tinh!A:A,MATCH(TRIM(AW516),Tinh!B:B,0)),"")} | AZ516: {=IFERROR(INDEX('Ngân Hàng'!B:B,MATCH(AY516,'Ngân Hàng'!C:C,0)),"")} | BD516: =IF(ISBLANK(BC516),"",INDEX(matinh,MATCH(BC516,ten_tinh,0))) | BF516: =IF(ISBLANK(BE516),"",INDEX(mahuyen,MATCH(CONCATENATE(BD516,"-",BE516),Loc_trung_huyen,0))) | BI516: =IF(ISBLANK(BH516),"",INDEX(matinh,MATCH(BH516,ten_tinh,0))) | BK516: =IF(ISBLANK(BJ516),"",INDEX(mahuyen,MATCH(CONCATENATE(BI516,"-",BJ516),Loc_trung_huyen,0))) | BN516: =IF(ISBLANK(BM516),"",INDEX(matinh,MATCH(BM516,ten_tinh,0))) | BP516: {=IF(ISBLANK(BO516),"",INDEX(mabenhvien,MATCH(BO516&BN516,tenbenhvien&matinhbenhvien,0)))} | BS516: =IF(ISBLANK(BR516),"",INDEX(matinh,MATCH(BR516,ten_tinh,0))) | BU516: =IF(ISBLANK(BT516),"",INDEX(mahuyen,MATCH(CONCATENATE(BS516,"-",BT516),Loc_trung_huyen,0))) | CI516: =IF(ISBLANK(CH516),"",INDEX(matinh,MATCH(CH516,ten_tinh,0))) | CK516: =IF(ISBLANK(CJ516),"",INDEX(mahuyen,MATCH(CONCATENATE(CI516,"-",CJ516),Loc_trung_huyen,0))) | CO516: =IF(ISBLANK(CN516),"",INDEX(matinh,MATCH(CN516,ten_tinh,0))) | CQ516: =IF(ISBLANK(CP516),"",INDEX(mahuyen,MATCH(CONCATENATE(CO516,"-",CP516),Loc_trung_huyen,0))) | CZ516: =IF(ISBLANK(CY516),"",INDEX(maquocgia,MATCH(CY516,dm_quocgia,0))) | DB516: =IF(ISBLANK(DA516),"",INDEX(madantoc,MATCH(DA516,tendantoc,0))) | DE516: =IF(ISBLANK(DD516),"",INDEX(mamoiquanhe,MATCH(DD516,moiquanhe,0))) | DG516: =IF(ISBLANK(DF516),"",INDEX(matinh,MATCH(DF516,ten_tinh,0))) | DI516: =IF(ISBLANK(DH516),"",INDEX(mahuyen,MATCH(CONCATENATE(DG516,"-",DH516),Loc_trung_huyen,0)))
E517: =IF(ISBLANK(D517),"",INDEX(maloaipa,MATCH(D517,loaipa,0))) | U517: =IF(ISBLANK(T517),"",INDEX(Ma_PA,MATCH(T517,'Phương án'!$C$3:C543,0))) | AT517: =IF(ISBLANK(AS517),"",INDEX(maquocgia,MATCH(AS517,dm_quocgia,0))) | AV517: =IF(ISBLANK(AU517),"",INDEX(madantoc,MATCH(AU517,tendantoc,0))) | AX517: {=IFERROR(INDEX(Tinh!A:A,MATCH(TRIM(AW517),Tinh!B:B,0)),"")} | AZ517: {=IFERROR(INDEX('Ngân Hàng'!B:B,MATCH(AY517,'Ngân Hàng'!C:C,0)),"")} | BD517: =IF(ISBLANK(BC517),"",INDEX(matinh,MATCH(BC517,ten_tinh,0))) | BF517: =IF(ISBLANK(BE517),"",INDEX(mahuyen,MATCH(CONCATENATE(BD517,"-",BE517),Loc_trung_huyen,0))) | BI517: =IF(ISBLANK(BH517),"",INDEX(matinh,MATCH(BH517,ten_tinh,0))) | BK517: =IF(ISBLANK(BJ517),"",INDEX(mahuyen,MATCH(CONCATENATE(BI517,"-",BJ517),Loc_trung_huyen,0))) | BN517: =IF(ISBLANK(BM517),"",INDEX(matinh,MATCH(BM517,ten_tinh,0))) | BP517: {=IF(ISBLANK(BO517),"",INDEX(mabenhvien,MATCH(BO517&BN517,tenbenhvien&matinhbenhvien,0)))} | BS517: =IF(ISBLANK(BR517),"",INDEX(matinh,MATCH(BR517,ten_tinh,0))) | BU517: =IF(ISBLANK(BT517),"",INDEX(mahuyen,MATCH(CONCATENATE(BS517,"-",BT517),Loc_trung_huyen,0))) | CI517: =IF(ISBLANK(CH517),"",INDEX(matinh,MATCH(CH517,ten_tinh,0))) | CK517: =IF(ISBLANK(CJ517),"",INDEX(mahuyen,MATCH(CONCATENATE(CI517,"-",CJ517),Loc_trung_huyen,0))) | CO517: =IF(ISBLANK(CN517),"",INDEX(matinh,MATCH(CN517,ten_tinh,0))) | CQ517: =IF(ISBLANK(CP517),"",INDEX(mahuyen,MATCH(CONCATENATE(CO517,"-",CP517),Loc_trung_huyen,0))) | CZ517: =IF(ISBLANK(CY517),"",INDEX(maquocgia,MATCH(CY517,dm_quocgia,0))) | DE517: =IF(ISBLANK(DD517),"",INDEX(mamoiquanhe,MATCH(DD517,moiquanhe,0))) | DG517: =IF(ISBLANK(DF517),"",INDEX(matinh,MATCH(DF517,ten_tinh,0))) | DI517: =IF(ISBLANK(DH517),"",INDEX(mahuyen,MATCH(CONCATENATE(DG517,"-",DH517),Loc_trung_huyen,0)))
E518: =IF(ISBLANK(D518),"",INDEX(maloaipa,MATCH(D518,loaipa,0))) | U518: =IF(ISBLANK(T518),"",INDEX(Ma_PA,MATCH(T518,'Phương án'!$C$3:C544,0))) | AT518: =IF(ISBLANK(AS518),"",INDEX(maquocgia,MATCH(AS518,dm_quocgia,0))) | AV518: =IF(ISBLANK(AU518),"",INDEX(madantoc,MATCH(AU518,tendantoc,0))) | AX518: {=IFERROR(INDEX(Tinh!A:A,MATCH(TRIM(AW518),Tinh!B:B,0)),"")} | AZ518: {=IFERROR(INDEX('Ngân Hàng'!B:B,MATCH(AY518,'Ngân Hàng'!C:C,0)),"")} | BD518: =IF(ISBLANK(BC518),"",INDEX(matinh,MATCH(BC518,ten_tinh,0))) | BF518: =IF(ISBLANK(BE518),"",INDEX(mahuyen,MATCH(CONCATENATE(BD518,"-",BE518),Loc_trung_huyen,0))) | BI518: =IF(ISBLANK(BH518),"",INDEX(matinh,MATCH(BH518,ten_tinh,0))) | BK518: =IF(ISBLANK(BJ518),"",INDEX(mahuyen,MATCH(CONCATENATE(BI518,"-",BJ518),Loc_trung_huyen,0))) | BN518: =IF(ISBLANK(BM518),"",INDEX(matinh,MATCH(BM518,ten_tinh,0))) | BP518: {=IF(ISBLANK(BO518),"",INDEX(mabenhvien,MATCH(BO518&BN518,tenbenhvien&matinhbenhvien,0)))} | BS518: =IF(ISBLANK(BR518),"",INDEX(matinh,MATCH(BR518,ten_tinh,0))) | BU518: =IF(ISBLANK(BT518),"",INDEX(mahuyen,MATCH(CONCATENATE(BS518,"-",BT518),Loc_trung_huyen,0))) | CI518: =IF(ISBLANK(CH518),"",INDEX(matinh,MATCH(CH518,ten_tinh,0))) | CK518: =IF(ISBLANK(CJ518),"",INDEX(mahuyen,MATCH(CONCATENATE(CI518,"-",CJ518),Loc_trung_huyen,0))) | CO518: =IF(ISBLANK(CN518),"",INDEX(matinh,MATCH(CN518,ten_tinh,0))) | CQ518: =IF(ISBLANK(CP518),"",INDEX(mahuyen,MATCH(CONCATENATE(CO518,"-",CP518),Loc_trung_huyen,0))) | CZ518: =IF(ISBLANK(CY518),"",INDEX(maquocgia,MATCH(CY518,dm_quocgia,0))) | DE518: =IF(ISBLANK(DD518),"",INDEX(mamoiquanhe,MATCH(DD518,moiquanhe,0))) | DG518: =IF(ISBLANK(DF518),"",INDEX(matinh,MATCH(DF518,ten_tinh,0))) | DI518: =IF(ISBLANK(DH518),"",INDEX(mahuyen,MATCH(CONCATENATE(DG518,"-",DH518),Loc_trung_huyen,0)))
E519: =IF(ISBLANK(D519),"",INDEX(maloaipa,MATCH(D519,loaipa,0))) | U519: =IF(ISBLANK(T519),"",INDEX(Ma_PA,MATCH(T519,'Phương án'!$C$3:C545,0))) | AT519: =IF(ISBLANK(AS519),"",INDEX(maquocgia,MATCH(AS519,dm_quocgia,0))) | AV519: =IF(ISBLANK(AU519),"",INDEX(madantoc,MATCH(AU519,tendantoc,0))) | AX519: {=IFERROR(INDEX(Tinh!A:A,MATCH(TRIM(AW519),Tinh!B:B,0)),"")} | AZ519: {=IFERROR(INDEX('Ngân Hàng'!B:B,MATCH(AY519,'Ngân Hàng'!C:C,0)),"")} | BD519: =IF(ISBLANK(BC519),"",INDEX(matinh,MATCH(BC519,ten_tinh,0))) | BF519: =IF(ISBLANK(BE519),"",INDEX(mahuyen,MATCH(CONCATENATE(BD519,"-",BE519),Loc_trung_huyen,0))) | BI519: =IF(ISBLANK(BH519),"",INDEX(matinh,MATCH(BH519,ten_tinh,0))) | BK519: =IF(ISBLANK(BJ519),"",INDEX(mahuyen,MATCH(CONCATENATE(BI519,"-",BJ519),Loc_trung_huyen,0))) | BN519: =IF(ISBLANK(BM519),"",INDEX(matinh,MATCH(BM519,ten_tinh,0))) | BP519: {=IF(ISBLANK(BO519),"",INDEX(mabenhvien,MATCH(BO519&BN519,tenbenhvien&matinhbenhvien,0)))} | BS519: =IF(ISBLANK(BR519),"",INDEX(matinh,MATCH(BR519,ten_tinh,0))) | BU519: =IF(ISBLANK(BT519),"",INDEX(mahuyen,MATCH(CONCATENATE(BS519,"-",BT519),Loc_trung_huyen,0))) | CI519: =IF(ISBLANK(CH519),"",INDEX(matinh,MATCH(CH519,ten_tinh,0))) | CK519: =IF(ISBLANK(CJ519),"",INDEX(mahuyen,MATCH(CONCATENATE(CI519,"-",CJ519),Loc_trung_huyen,0))) | CO519: =IF(ISBLANK(CN519),"",INDEX(matinh,MATCH(CN519,ten_tinh,0))) | CQ519: =IF(ISBLANK(CP519),"",INDEX(mahuyen,MATCH(CONCATENATE(CO519,"-",CP519),Loc_trung_huyen,0))) | CZ519: =IF(ISBLANK(CY519),"",INDEX(maquocgia,MATCH(CY519,dm_quocgia,0))) | DE519: =IF(ISBLANK(DD519),"",INDEX(mamoiquanhe,MATCH(DD519,moiquanhe,0))) | DG519: =IF(ISBLANK(DF519),"",INDEX(matinh,MATCH(DF519,ten_tinh,0))) | DI519: =IF(ISBLANK(DH519),"",INDEX(mahuyen,MATCH(CONCATENATE(DG519,"-",DH519),Loc_trung_huyen,0)))
E520: =IF(ISBLANK(D520),"",INDEX(maloaipa,MATCH(D520,loaipa,0))) | U520: =IF(ISBLANK(T520),"",INDEX(Ma_PA,MATCH(T520,'Phương án'!$C$3:C546,0))) | AT520: =IF(ISBLANK(AS520),"",INDEX(maquocgia,MATCH(AS520,dm_quocgia,0))) | AV520: =IF(ISBLANK(AU520),"",INDEX(madantoc,MATCH(AU520,tendantoc,0))) | AX520: {=IFERROR(INDEX(Tinh!A:A,MATCH(TRIM(AW520),Tinh!B:B,0)),"")} | AZ520: {=IFERROR(INDEX('Ngân Hàng'!B:B,MATCH(AY520,'Ngân Hàng'!C:C,0)),"")} | BD520: =IF(ISBLANK(BC520),"",INDEX(matinh,MATCH(BC520,ten_tinh,0))) | BF520: =IF(ISBLANK(BE520),"",INDEX(mahuyen,MATCH(CONCATENATE(BD520,"-",BE520),Loc_trung_huyen,0))) | BI520: =IF(ISBLANK(BH520),"",INDEX(matinh,MATCH(BH520,ten_tinh,0))) | BK520: =IF(ISBLANK(BJ520),"",INDEX(mahuyen,MATCH(CONCATENATE(BI520,"-",BJ520),Loc_trung_huyen,0))) | BN520: =IF(ISBLANK(BM520),"",INDEX(matinh,MATCH(BM520,ten_tinh,0))) | BP520: {=IF(ISBLANK(BO520),"",INDEX(mabenhvien,MATCH(BO520&BN520,tenbenhvien&matinhbenhvien,0)))} | BS520: =IF(ISBLANK(BR520),"",INDEX(matinh,MATCH(BR520,ten_tinh,0))) | BU520: =IF(ISBLANK(BT520),"",INDEX(mahuyen,MATCH(CONCATENATE(BS520,"-",BT520),Loc_trung_huyen,0))) | CI520: =IF(ISBLANK(CH520),"",INDEX(matinh,MATCH(CH520,ten_tinh,0))) | CK520: =IF(ISBLANK(CJ520),"",INDEX(mahuyen,MATCH(CONCATENATE(CI520,"-",CJ520),Loc_trung_huyen,0))) | CO520: =IF(ISBLANK(CN520),"",INDEX(matinh,MATCH(CN520,ten_tinh,0))) | CQ520: =IF(ISBLANK(CP520),"",INDEX(mahuyen,MATCH(CONCATENATE(CO520,"-",CP520),Loc_trung_huyen,0))) | CZ520: =IF(ISBLANK(CY520),"",INDEX(maquocgia,MATCH(CY520,dm_quocgia,0))) | DE520: =IF(ISBLANK(DD520),"",INDEX(mamoiquanhe,MATCH(DD520,moiquanhe,0))) | DG520: =IF(ISBLANK(DF520),"",INDEX(matinh,MATCH(DF520,ten_tinh,0))) | DI520: =IF(ISBLANK(DH520),"",INDEX(mahuyen,MATCH(CONCATENATE(DG520,"-",DH520),Loc_trung_huyen,0)))
E521: =IF(ISBLANK(D521),"",INDEX(maloaipa,MATCH(D521,loaipa,0))) | U521: =IF(ISBLANK(T521),"",INDEX(Ma_PA,MATCH(T521,'Phương án'!$C$3:C547,0))) | AT521: =IF(ISBLANK(AS521),"",INDEX(maquocgia,MATCH(AS521,dm_quocgia,0))) | AV521: =IF(ISBLANK(AU521),"",INDEX(madantoc,MATCH(AU521,tendantoc,0))) | AX521: {=IFERROR(INDEX(Tinh!A:A,MATCH(TRIM(AW521),Tinh!B:B,0)),"")} | AZ521: {=IFERROR(INDEX('Ngân Hàng'!B:B,MATCH(AY521,'Ngân Hàng'!C:C,0)),"")} | BD521: =IF(ISBLANK(BC521),"",INDEX(matinh,MATCH(BC521,ten_tinh,0))) | BF521: =IF(ISBLANK(BE521),"",INDEX(mahuyen,MATCH(CONCATENATE(BD521,"-",BE521),Loc_trung_huyen,0))) | BI521: =IF(ISBLANK(BH521),"",INDEX(matinh,MATCH(BH521,ten_tinh,0))) | BK521: =IF(ISBLANK(BJ521),"",INDEX(mahuyen,MATCH(CONCATENATE(BI521,"-",BJ521),Loc_trung_huyen,0))) | BN521: =IF(ISBLANK(BM521),"",INDEX(matinh,MATCH(BM521,ten_tinh,0))) | BP521: {=IF(ISBLANK(BO521),"",INDEX(mabenhvien,MATCH(BO521&BN521,tenbenhvien&matinhbenhvien,0)))} | BS521: =IF(ISBLANK(BR521),"",INDEX(matinh,MATCH(BR521,ten_tinh,0))) | BU521: =IF(ISBLANK(BT521),"",INDEX(mahuyen,MATCH(CONCATENATE(BS521,"-",BT521),Loc_trung_huyen,0))) | CI521: =IF(ISBLANK(CH521),"",INDEX(matinh,MATCH(CH521,ten_tinh,0))) | CK521: =IF(ISBLANK(CJ521),"",INDEX(mahuyen,MATCH(CONCATENATE(CI521,"-",CJ521),Loc_trung_huyen,0))) | CO521: =IF(ISBLANK(CN521),"",INDEX(matinh,MATCH(CN521,ten_tinh,0))) | CQ521: =IF(ISBLANK(CP521),"",INDEX(mahuyen,MATCH(CONCATENATE(CO521,"-",CP521),Loc_trung_huyen,0))) | CZ521: =IF(ISBLANK(CY521),"",INDEX(maquocgia,MATCH(CY521,dm_quocgia,0))) | DE521: =IF(ISBLANK(DD521),"",INDEX(mamoiquanhe,MATCH(DD521,moiquanhe,0))) | DG521: =IF(ISBLANK(DF521),"",INDEX(matinh,MATCH(DF521,ten_tinh,0))) | DI521: =IF(ISBLANK(DH521),"",INDEX(mahuyen,MATCH(CONCATENATE(DG521,"-",DH521),Loc_trung_huyen,0)))
E522: =IF(ISBLANK(D522),"",INDEX(maloaipa,MATCH(D522,loaipa,0))) | U522: =IF(ISBLANK(T522),"",INDEX(Ma_PA,MATCH(T522,'Phương án'!$C$3:C548,0))) | AT522: =IF(ISBLANK(AS522),"",INDEX(maquocgia,MATCH(AS522,dm_quocgia,0))) | AV522: =IF(ISBLANK(AU522),"",INDEX(madantoc,MATCH(AU522,tendantoc,0))) | AX522: {=IFERROR(INDEX(Tinh!A:A,MATCH(TRIM(AW522),Tinh!B:B,0)),"")} | AZ522: {=IFERROR(INDEX('Ngân Hàng'!B:B,MATCH(AY522,'Ngân Hàng'!C:C,0)),"")} | BD522: =IF(ISBLANK(BC522),"",INDEX(matinh,MATCH(BC522,ten_tinh,0))) | BF522: =IF(ISBLANK(BE522),"",INDEX(mahuyen,MATCH(CONCATENATE(BD522,"-",BE522),Loc_trung_huyen,0))) | BI522: =IF(ISBLANK(BH522),"",INDEX(matinh,MATCH(BH522,ten_tinh,0))) | BK522: =IF(ISBLANK(BJ522),"",INDEX(mahuyen,MATCH(CONCATENATE(BI522,"-",BJ522),Loc_trung_huyen,0))) | BN522: =IF(ISBLANK(BM522),"",INDEX(matinh,MATCH(BM522,ten_tinh,0))) | BP522: {=IF(ISBLANK(BO522),"",INDEX(mabenhvien,MATCH(BO522&BN522,tenbenhvien&matinhbenhvien,0)))} | BS522: =IF(ISBLANK(BR522),"",INDEX(matinh,MATCH(BR522,ten_tinh,0))) | BU522: =IF(ISBLANK(BT522),"",INDEX(mahuyen,MATCH(CONCATENATE(BS522,"-",BT522),Loc_trung_huyen,0))) | CI522: =IF(ISBLANK(CH522),"",INDEX(matinh,MATCH(CH522,ten_tinh,0))) | CK522: =IF(ISBLANK(CJ522),"",INDEX(mahuyen,MATCH(CONCATENATE(CI522,"-",CJ522),Loc_trung_huyen,0))) | CO522: =IF(ISBLANK(CN522),"",INDEX(matinh,MATCH(CN522,ten_tinh,0))) | CQ522: =IF(ISBLANK(CP522),"",INDEX(mahuyen,MATCH(CONCATENATE(CO522,"-",CP522),Loc_trung_huyen,0))) | CZ522: =IF(ISBLANK(CY522),"",INDEX(maquocgia,MATCH(CY522,dm_quocgia,0))) | DE522: =IF(ISBLANK(DD522),"",INDEX(mamoiquanhe,MATCH(DD522,moiquanhe,0))) | DG522: =IF(ISBLANK(DF522),"",INDEX(matinh,MATCH(DF522,ten_tinh,0))) | DI522: =IF(ISBLANK(DH522),"",INDEX(mahuyen,MATCH(CONCATENATE(DG522,"-",DH522),Loc_trung_huyen,0)))
E523: =IF(ISBLANK(D523),"",INDEX(maloaipa,MATCH(D523,loaipa,0))) | U523: =IF(ISBLANK(T523),"",INDEX(Ma_PA,MATCH(T523,'Phương án'!$C$3:C549,0))) | AT523: =IF(ISBLANK(AS523),"",INDEX(maquocgia,MATCH(AS523,dm_quocgia,0))) | AV523: =IF(ISBLANK(AU523),"",INDEX(madantoc,MATCH(AU523,tendantoc,0))) | AX523: {=IFERROR(INDEX(Tinh!A:A,MATCH(TRIM(AW523),Tinh!B:B,0)),"")} | AZ523: {=IFERROR(INDEX('Ngân Hàng'!B:B,MATCH(AY523,'Ngân Hàng'!C:C,0)),"")} | BD523: =IF(ISBLANK(BC523),"",INDEX(matinh,MATCH(BC523,ten_tinh,0))) | BF523: =IF(ISBLANK(BE523),"",INDEX(mahuyen,MATCH(CONCATENATE(BD523,"-",BE523),Loc_trung_huyen,0))) | BI523: =IF(ISBLANK(BH523),"",INDEX(matinh,MATCH(BH523,ten_tinh,0))) | BK523: =IF(ISBLANK(BJ523),"",INDEX(mahuyen,MATCH(CONCATENATE(BI523,"-",BJ523),Loc_trung_huyen,0))) | BN523: =IF(ISBLANK(BM523),"",INDEX(matinh,MATCH(BM523,ten_tinh,0))) | BP523: {=IF(ISBLANK(BO523),"",INDEX(mabenhvien,MATCH(BO523&BN523,tenbenhvien&matinhbenhvien,0)))} | BS523: =IF(ISBLANK(BR523),"",INDEX(matinh,MATCH(BR523,ten_tinh,0))) | BU523: =IF(ISBLANK(BT523),"",INDEX(mahuyen,MATCH(CONCATENATE(BS523,"-",BT523),Loc_trung_huyen,0))) | CI523: =IF(ISBLANK(CH523),"",INDEX(matinh,MATCH(CH523,ten_tinh,0))) | CK523: =IF(ISBLANK(CJ523),"",INDEX(mahuyen,MATCH(CONCATENATE(CI523,"-",CJ523),Loc_trung_huyen,0))) | CO523: =IF(ISBLANK(CN523),"",INDEX(matinh,MATCH(CN523,ten_tinh,0))) | CQ523: =IF(ISBLANK(CP523),"",INDEX(mahuyen,MATCH(CONCATENATE(CO523,"-",CP523),Loc_trung_huyen,0))) | CZ523: =IF(ISBLANK(CY523),"",INDEX(maquocgia,MATCH(CY523,dm_quocgia,0))) | DE523: =IF(ISBLANK(DD523),"",INDEX(mamoiquanhe,MATCH(DD523,moiquanhe,0))) | DG523: =IF(ISBLANK(DF523),"",INDEX(matinh,MATCH(DF523,ten_tinh,0))) | DI523: =IF(ISBLANK(DH523),"",INDEX(mahuyen,MATCH(CONCATENATE(DG523,"-",DH523),Loc_trung_huyen,0)))
E524: =IF(ISBLANK(D524),"",INDEX(maloaipa,MATCH(D524,loaipa,0))) | U524: =IF(ISBLANK(T524),"",INDEX(Ma_PA,MATCH(T524,'Phương án'!$C$3:C550,0))) | AT524: =IF(ISBLANK(AS524),"",INDEX(maquocgia,MATCH(AS524,dm_quocgia,0))) | AV524: =IF(ISBLANK(AU524),"",INDEX(madantoc,MATCH(AU524,tendantoc,0))) | AX524: {=IFERROR(INDEX(Tinh!A:A,MATCH(TRIM(AW524),Tinh!B:B,0)),"")} | AZ524: {=IFERROR(INDEX('Ngân Hàng'!B:B,MATCH(AY524,'Ngân Hàng'!C:C,0)),"")} | BD524: =IF(ISBLANK(BC524),"",INDEX(matinh,MATCH(BC524,ten_tinh,0))) | BF524: =IF(ISBLANK(BE524),"",INDEX(mahuyen,MATCH(CONCATENATE(BD524,"-",BE524),Loc_trung_huyen,0))) | BI524: =IF(ISBLANK(BH524),"",INDEX(matinh,MATCH(BH524,ten_tinh,0))) | BK524: =IF(ISBLANK(BJ524),"",INDEX(mahuyen,MATCH(CONCATENATE(BI524,"-",BJ524),Loc_trung_huyen,0))) | BN524: =IF(ISBLANK(BM524),"",INDEX(matinh,MATCH(BM524,ten_tinh,0))) | BP524: {=IF(ISBLANK(BO524),"",INDEX(mabenhvien,MATCH(BO524&BN524,tenbenhvien&matinhbenhvien,0)))} | BS524: =IF(ISBLANK(BR524),"",INDEX(matinh,MATCH(BR524,ten_tinh,0))) | BU524: =IF(ISBLANK(BT524),"",INDEX(mahuyen,MATCH(CONCATENATE(BS524,"-",BT524),Loc_trung_huyen,0))) | CI524: =IF(ISBLANK(CH524),"",INDEX(matinh,MATCH(CH524,ten_tinh,0))) | CK524: =IF(ISBLANK(CJ524),"",INDEX(mahuyen,MATCH(CONCATENATE(CI524,"-",CJ524),Loc_trung_huyen,0))) | CO524: =IF(ISBLANK(CN524),"",INDEX(matinh,MATCH(CN524,ten_tinh,0))) | CQ524: =IF(ISBLANK(CP524),"",INDEX(mahuyen,MATCH(CONCATENATE(CO524,"-",CP524),Loc_trung_huyen,0))) | CZ524: =IF(ISBLANK(CY524),"",INDEX(maquocgia,MATCH(CY524,dm_quocgia,0))) | DE524: =IF(ISBLANK(DD524),"",INDEX(mamoiquanhe,MATCH(DD524,moiquanhe,0))) | DG524: =IF(ISBLANK(DF524),"",INDEX(matinh,MATCH(DF524,ten_tinh,0))) | DI524: =IF(ISBLANK(DH524),"",INDEX(mahuyen,MATCH(CONCATENATE(DG524,"-",DH524),Loc_trung_huyen,0)))
E525: =IF(ISBLANK(D525),"",INDEX(maloaipa,MATCH(D525,loaipa,0))) | U525: =IF(ISBLANK(T525),"",INDEX(Ma_PA,MATCH(T525,'Phương án'!$C$3:C551,0))) | AT525: =IF(ISBLANK(AS525),"",INDEX(maquocgia,MATCH(AS525,dm_quocgia,0))) | AV525: =IF(ISBLANK(AU525),"",INDEX(madantoc,MATCH(AU525,tendantoc,0))) | AX525: {=IFERROR(INDEX(Tinh!A:A,MATCH(TRIM(AW525),Tinh!B:B,0)),"")} | AZ525: {=IFERROR(INDEX('Ngân Hàng'!B:B,MATCH(AY525,'Ngân Hàng'!C:C,0)),"")} | BD525: =IF(ISBLANK(BC525),"",INDEX(matinh,MATCH(BC525,ten_tinh,0))) | BF525: =IF(ISBLANK(BE525),"",INDEX(mahuyen,MATCH(CONCATENATE(BD525,"-",BE525),Loc_trung_huyen,0))) | BI525: =IF(ISBLANK(BH525),"",INDEX(matinh,MATCH(BH525,ten_tinh,0))) | BK525: =IF(ISBLANK(BJ525),"",INDEX(mahuyen,MATCH(CONCATENATE(BI525,"-",BJ525),Loc_trung_huyen,0))) | BN525: =IF(ISBLANK(BM525),"",INDEX(matinh,MATCH(BM525,ten_tinh,0))) | BP525: {=IF(ISBLANK(BO525),"",INDEX(mabenhvien,MATCH(BO525&BN525,tenbenhvien&matinhbenhvien,0)))} | BS525: =IF(ISBLANK(BR525),"",INDEX(matinh,MATCH(BR525,ten_tinh,0))) | BU525: =IF(ISBLANK(BT525),"",INDEX(mahuyen,MATCH(CONCATENATE(BS525,"-",BT525),Loc_trung_huyen,0))) | CI525: =IF(ISBLANK(CH525),"",INDEX(matinh,MATCH(CH525,ten_tinh,0))) | CK525: =IF(ISBLANK(CJ525),"",INDEX(mahuyen,MATCH(CONCATENATE(CI525,"-",CJ525),Loc_trung_huyen,0))) | CO525: =IF(ISBLANK(CN525),"",INDEX(matinh,MATCH(CN525,ten_tinh,0))) | CQ525: =IF(ISBLANK(CP525),"",INDEX(mahuyen,MATCH(CONCATENATE(CO525,"-",CP525),Loc_trung_huyen,0))) | CZ525: =IF(ISBLANK(CY525),"",INDEX(maquocgia,MATCH(CY525,dm_quocgia,0))) | DE525: =IF(ISBLANK(DD525),"",INDEX(mamoiquanhe,MATCH(DD525,moiquanhe,0))) | DG525: =IF(ISBLANK(DF525),"",INDEX(matinh,MATCH(DF525,ten_tinh,0))) | DI525: =IF(ISBLANK(DH525),"",INDEX(mahuyen,MATCH(CONCATENATE(DG525,"-",DH525),Loc_trung_huyen,0)))
E526: =IF(ISBLANK(D526),"",INDEX(maloaipa,MATCH(D526,loaipa,0))) | U526: =IF(ISBLANK(T526),"",INDEX(Ma_PA,MATCH(T526,'Phương án'!$C$3:C552,0))) | AT526: =IF(ISBLANK(AS526),"",INDEX(maquocgia,MATCH(AS526,dm_quocgia,0))) | AV526: =IF(ISBLANK(AU526),"",INDEX(madantoc,MATCH(AU526,tendantoc,0))) | AX526: {=IFERROR(INDEX(Tinh!A:A,MATCH(TRIM(AW526),Tinh!B:B,0)),"")} | AZ526: {=IFERROR(INDEX('Ngân Hàng'!B:B,MATCH(AY526,'Ngân Hàng'!C:C,0)),"")} | BD526: =IF(ISBLANK(BC526),"",INDEX(matinh,MATCH(BC526,ten_tinh,0))) | BF526: =IF(ISBLANK(BE526),"",INDEX(mahuyen,MATCH(CONCATENATE(BD526,"-",BE526),Loc_trung_huyen,0))) | BI526: =IF(ISBLANK(BH526),"",INDEX(matinh,MATCH(BH526,ten_tinh,0))) | BK526: =IF(ISBLANK(BJ526),"",INDEX(mahuyen,MATCH(CONCATENATE(BI526,"-",BJ526),Loc_trung_huyen,0))) | BN526: =IF(ISBLANK(BM526),"",INDEX(matinh,MATCH(BM526,ten_tinh,0))) | BP526: {=IF(ISBLANK(BO526),"",INDEX(mabenhvien,MATCH(BO526&BN526,tenbenhvien&matinhbenhvien,0)))} | BS526: =IF(ISBLANK(BR526),"",INDEX(matinh,MATCH(BR526,ten_tinh,0))) | BU526: =IF(ISBLANK(BT526),"",INDEX(mahuyen,MATCH(CONCATENATE(BS526,"-",BT526),Loc_trung_huyen,0))) | CI526: =IF(ISBLANK(CH526),"",INDEX(matinh,MATCH(CH526,ten_tinh,0))) | CK526: =IF(ISBLANK(CJ526),"",INDEX(mahuyen,MATCH(CONCATENATE(CI526,"-",CJ526),Loc_trung_huyen,0))) | CO526: =IF(ISBLANK(CN526),"",INDEX(matinh,MATCH(CN526,ten_tinh,0))) | CQ526: =IF(ISBLANK(CP526),"",INDEX(mahuyen,MATCH(CONCATENATE(CO526,"-",CP526),Loc_trung_huyen,0))) | CZ526: =IF(ISBLANK(CY526),"",INDEX(maquocgia,MATCH(CY526,dm_quocgia,0))) | DE526: =IF(ISBLANK(DD526),"",INDEX(mamoiquanhe,MATCH(DD526,moiquanhe,0))) | DG526: =IF(ISBLANK(DF526),"",INDEX(matinh,MATCH(DF526,ten_tinh,0))) | DI526: =IF(ISBLANK(DH526),"",INDEX(mahuyen,MATCH(CONCATENATE(DG526,"-",DH526),Loc_trung_huyen,0)))
E527: =IF(ISBLANK(D527),"",INDEX(maloaipa,MATCH(D527,loaipa,0))) | U527: =IF(ISBLANK(T527),"",INDEX(Ma_PA,MATCH(T527,'Phương án'!$C$3:C553,0))) | AT527: =IF(ISBLANK(AS527),"",INDEX(maquocgia,MATCH(AS527,dm_quocgia,0))) | AV527: =IF(ISBLANK(AU527),"",INDEX(madantoc,MATCH(AU527,tendantoc,0))) | AX527: {=IFERROR(INDEX(Tinh!A:A,MATCH(TRIM(AW527),Tinh!B:B,0)),"")} | AZ527: {=IFERROR(INDEX('Ngân Hàng'!B:B,MATCH(AY527,'Ngân Hàng'!C:C,0)),"")} | BD527: =IF(ISBLANK(BC527),"",INDEX(matinh,MATCH(BC527,ten_tinh,0))) | BF527: =IF(ISBLANK(BE527),"",INDEX(mahuyen,MATCH(CONCATENATE(BD527,"-",BE527),Loc_trung_huyen,0))) | BI527: =IF(ISBLANK(BH527),"",INDEX(matinh,MATCH(BH527,ten_tinh,0))) | BK527: =IF(ISBLANK(BJ527),"",INDEX(mahuyen,MATCH(CONCATENATE(BI527,"-",BJ527),Loc_trung_huyen,0))) | BN527: =IF(ISBLANK(BM527),"",INDEX(matinh,MATCH(BM527,ten_tinh,0))) | BP527: {=IF(ISBLANK(BO527),"",INDEX(mabenhvien,MATCH(BO527&BN527,tenbenhvien&matinhbenhvien,0)))} | BS527: =IF(ISBLANK(BR527),"",INDEX(matinh,MATCH(BR527,ten_tinh,0))) | BU527: =IF(ISBLANK(BT527),"",INDEX(mahuyen,MATCH(CONCATENATE(BS527,"-",BT527),Loc_trung_huyen,0))) | CI527: =IF(ISBLANK(CH527),"",INDEX(matinh,MATCH(CH527,ten_tinh,0))) | CK527: =IF(ISBLANK(CJ527),"",INDEX(mahuyen,MATCH(CONCATENATE(CI527,"-",CJ527),Loc_trung_huyen,0))) | CO527: =IF(ISBLANK(CN527),"",INDEX(matinh,MATCH(CN527,ten_tinh,0))) | CQ527: =IF(ISBLANK(CP527),"",INDEX(mahuyen,MATCH(CONCATENATE(CO527,"-",CP527),Loc_trung_huyen,0))) | CZ527: =IF(ISBLANK(CY527),"",INDEX(maquocgia,MATCH(CY527,dm_quocgia,0))) | DE527: =IF(ISBLANK(DD527),"",INDEX(mamoiquanhe,MATCH(DD527,moiquanhe,0))) | DG527: =IF(ISBLANK(DF527),"",INDEX(matinh,MATCH(DF527,ten_tinh,0))) | DI527: =IF(ISBLANK(DH527),"",INDEX(mahuyen,MATCH(CONCATENATE(DG527,"-",DH527),Loc_trung_huyen,0)))
E528: =IF(ISBLANK(D528),"",INDEX(maloaipa,MATCH(D528,loaipa,0))) | U528: =IF(ISBLANK(T528),"",INDEX(Ma_PA,MATCH(T528,'Phương án'!$C$3:C554,0))) | AT528: =IF(ISBLANK(AS528),"",INDEX(maquocgia,MATCH(AS528,dm_quocgia,0))) | AV528: =IF(ISBLANK(AU528),"",INDEX(madantoc,MATCH(AU528,tendantoc,0))) | AX528: {=IFERROR(INDEX(Tinh!A:A,MATCH(TRIM(AW528),Tinh!B:B,0)),"")} | AZ528: {=IFERROR(INDEX('Ngân Hàng'!B:B,MATCH(AY528,'Ngân Hàng'!C:C,0)),"")} | BD528: =IF(ISBLANK(BC528),"",INDEX(matinh,MATCH(BC528,ten_tinh,0))) | BF528: =IF(ISBLANK(BE528),"",INDEX(mahuyen,MATCH(CONCATENATE(BD528,"-",BE528),Loc_trung_huyen,0))) | BI528: =IF(ISBLANK(BH528),"",INDEX(matinh,MATCH(BH528,ten_tinh,0))) | BK528: =IF(ISBLANK(BJ528),"",INDEX(mahuyen,MATCH(CONCATENATE(BI528,"-",BJ528),Loc_trung_huyen,0))) | BN528: =IF(ISBLANK(BM528),"",INDEX(matinh,MATCH(BM528,ten_tinh,0))) | BP528: {=IF(ISBLANK(BO528),"",INDEX(mabenhvien,MATCH(BO528&BN528,tenbenhvien&matinhbenhvien,0)))} | BS528: =IF(ISBLANK(BR528),"",INDEX(matinh,MATCH(BR528,ten_tinh,0))) | BU528: =IF(ISBLANK(BT528),"",INDEX(mahuyen,MATCH(CONCATENATE(BS528,"-",BT528),Loc_trung_huyen,0))) | CI528: =IF(ISBLANK(CH528),"",INDEX(matinh,MATCH(CH528,ten_tinh,0))) | CK528: =IF(ISBLANK(CJ528),"",INDEX(mahuyen,MATCH(CONCATENATE(CI528,"-",CJ528),Loc_trung_huyen,0))) | CO528: =IF(ISBLANK(CN528),"",INDEX(matinh,MATCH(CN528,ten_tinh,0))) | CQ528: =IF(ISBLANK(CP528),"",INDEX(mahuyen,MATCH(CONCATENATE(CO528,"-",CP528),Loc_trung_huyen,0))) | CZ528: =IF(ISBLANK(CY528),"",INDEX(maquocgia,MATCH(CY528,dm_quocgia,0))) | DE528: =IF(ISBLANK(DD528),"",INDEX(mamoiquanhe,MATCH(DD528,moiquanhe,0))) | DG528: =IF(ISBLANK(DF528),"",INDEX(matinh,MATCH(DF528,ten_tinh,0))) | DI528: =IF(ISBLANK(DH528),"",INDEX(mahuyen,MATCH(CONCATENATE(DG528,"-",DH528),Loc_trung_huyen,0)))
... E552: =IF(ISBLANK(D552),"",INDEX(maloaipa,MATCH(D552,loaipa,0))) | U552: =IF(ISBLANK(T552),"",INDEX(Ma_PA,MATCH(T552,'Phương án'!$C$3:C578,0))) | AT552: =IF(ISBLANK(AS552),"",INDEX(maquocgia,MATCH(AS552,dm_quocgia,0))) | AV552: =IF(ISBLANK(AU552),"",INDEX(madantoc,MATCH(AU552,tendantoc,0))) | AX552: {=IFERROR(INDEX(Tinh!A:A,MATCH(TRIM(AW552),Tinh!B:B,0)),"")} | AZ552: {=IFERROR(INDEX('Ngân Hàng'!B:B,MATCH(AY552,'Ngân Hàng'!C:C,0)),"")} | BD552: =IF(ISBLANK(BC552),"",INDEX(matinh,MATCH(BC552,ten_tinh,0))) | BF552: =IF(ISBLANK(BE552),"",INDEX(mahuyen,MATCH(CONCATENATE(BD552,"-",BE552),Loc_trung_huyen,0))) | BI552: =IF(ISBLANK(BH552),"",INDEX(matinh,MATCH(BH552,ten_tinh,0))) | BK552: =IF(ISBLANK(BJ552),"",INDEX(mahuyen,MATCH(CONCATENATE(BI552,"-",BJ552),Loc_trung_huyen,0))) | BN552: =IF(ISBLANK(BM552),"",INDEX(matinh,MATCH(BM552,ten_tinh,0))) | BP552: {=IF(ISBLANK(BO552),"",INDEX(mabenhvien,MATCH(BO552&BN552,tenbenhvien&matinhbenhvien,0)))} | BS552: =IF(ISBLANK(BR552),"",INDEX(matinh,MATCH(BR552,ten_tinh,0))) | BU552: =IF(ISBLANK(BT552),"",INDEX(mahuyen,MATCH(CONCATENATE(BS552,"-",BT552),Loc_trung_huyen,0))) | CI552: =IF(ISBLANK(CH552),"",INDEX(matinh,MATCH(CH552,ten_tinh,0))) | CK552: =IF(ISBLANK(CJ552),"",INDEX(mahuyen,MATCH(CONCATENATE(CI552,"-",CJ552),Loc_trung_huyen,0))) | CO552: =IF(ISBLANK(CN552),"",INDEX(matinh,MATCH(CN552,ten_tinh,0))) | CQ552: =IF(ISBLANK(CP552),"",INDEX(mahuyen,MATCH(CONCATENATE(CO552,"-",CP552),Loc_trung_huyen,0))) | CZ552: =IF(ISBLANK(CY552),"",INDEX(maquocgia,MATCH(CY552,dm_quocgia,0))) | DE552: =IF(ISBLANK(DD552),"",INDEX(mamoiquanhe,MATCH(DD552,moiquanhe,0))) | DG552: =IF(ISBLANK(DF552),"",INDEX(matinh,MATCH(DF552,ten_tinh,0))) | DI552: =IF(ISBLANK(DH552),"",INDEX(mahuyen,MATCH(CONCATENATE(DG552,"-",DH552),Loc_trung_huyen,0)))
E553: =IF(ISBLANK(D553),"",INDEX(maloaipa,MATCH(D553,loaipa,0))) | AT553: =IF(ISBLANK(AS553),"",INDEX(maquocgia,MATCH(AS553,dm_quocgia,0))) | AV553: =IF(ISBLANK(AU553),"",INDEX(madantoc,MATCH(AU553,tendantoc,0))) | AX553: {=IFERROR(INDEX(Tinh!A:A,MATCH(TRIM(AW553),Tinh!B:B,0)),"")} | AZ553: {=IFERROR(INDEX('Ngân Hàng'!B:B,MATCH(AY553,'Ngân Hàng'!C:C,0)),"")} | BD553: =IF(ISBLANK(BC553),"",INDEX(matinh,MATCH(BC553,ten_tinh,0))) | BF553: =IF(ISBLANK(BE553),"",INDEX(mahuyen,MATCH(CONCATENATE(BD553,"-",BE553),Loc_trung_huyen,0))) | BI553: =IF(ISBLANK(BH553),"",INDEX(matinh,MATCH(BH553,ten_tinh,0))) | BK553: =IF(ISBLANK(BJ553),"",INDEX(mahuyen,MATCH(CONCATENATE(BI553,"-",BJ553),Loc_trung_huyen,0))) | BN553: =IF(ISBLANK(BM553),"",INDEX(matinh,MATCH(BM553,ten_tinh,0))) | BP553: {=IF(ISBLANK(BO553),"",INDEX(mabenhvien,MATCH(BO553&BN553,tenbenhvien&matinhbenhvien,0)))} | BS553: =IF(ISBLANK(BR553),"",INDEX(matinh,MATCH(BR553,ten_tinh,0))) | BU553: =IF(ISBLANK(BT553),"",INDEX(mahuyen,MATCH(CONCATENATE(BS553,"-",BT553),Loc_trung_huyen,0))) | CI553: =IF(ISBLANK(CH553),"",INDEX(matinh,MATCH(CH553,ten_tinh,0))) | CK553: =IF(ISBLANK(CJ553),"",INDEX(mahuyen,MATCH(CONCATENATE(CI553,"-",CJ553),Loc_trung_huyen,0))) | CO553: =IF(ISBLANK(CN553),"",INDEX(matinh,MATCH(CN553,ten_tinh,0))) | CQ553: =IF(ISBLANK(CP553),"",INDEX(mahuyen,MATCH(CONCATENATE(CO553,"-",CP553),Loc_trung_huyen,0))) | CZ553: =IF(ISBLANK(CY553),"",INDEX(maquocgia,MATCH(CY553,dm_quocgia,0))) | DE553: =IF(ISBLANK(DD553),"",INDEX(mamoiquanhe,MATCH(DD553,moiquanhe,0))) | DG553: =IF(ISBLANK(DF553),"",INDEX(matinh,MATCH(DF553,ten_tinh,0))) | DI553: =IF(ISBLANK(DH553),"",INDEX(mahuyen,MATCH(CONCATENATE(DG553,"-",DH553),Loc_trung_huyen,0)))
E554: =IF(ISBLANK(D554),"",INDEX(maloaipa,MATCH(D554,loaipa,0))) | AT554: =IF(ISBLANK(AS554),"",INDEX(maquocgia,MATCH(AS554,dm_quocgia,0))) | AV554: =IF(ISBLANK(AU554),"",INDEX(madantoc,MATCH(AU554,tendantoc,0))) | AX554: {=IFERROR(INDEX(Tinh!A:A,MATCH(TRIM(AW554),Tinh!B:B,0)),"")} | AZ554: {=IFERROR(INDEX('Ngân Hàng'!B:B,MATCH(AY554,'Ngân Hàng'!C:C,0)),"")} | BD554: =IF(ISBLANK(BC554),"",INDEX(matinh,MATCH(BC554,ten_tinh,0))) | BF554: =IF(ISBLANK(BE554),"",INDEX(mahuyen,MATCH(CONCATENATE(BD554,"-",BE554),Loc_trung_huyen,0))) | BI554: =IF(ISBLANK(BH554),"",INDEX(matinh,MATCH(BH554,ten_tinh,0))) | BK554: =IF(ISBLANK(BJ554),"",INDEX(mahuyen,MATCH(CONCATENATE(BI554,"-",BJ554),Loc_trung_huyen,0))) | BN554: =IF(ISBLANK(BM554),"",INDEX(matinh,MATCH(BM554,ten_tinh,0))) | BP554: {=IF(ISBLANK(BO554),"",INDEX(mabenhvien,MATCH(BO554&BN554,tenbenhvien&matinhbenhvien,0)))} | BS554: =IF(ISBLANK(BR554),"",INDEX(matinh,MATCH(BR554,ten_tinh,0))) | BU554: =IF(ISBLANK(BT554),"",INDEX(mahuyen,MATCH(CONCATENATE(BS554,"-",BT554),Loc_trung_huyen,0))) | CI554: =IF(ISBLANK(CH554),"",INDEX(matinh,MATCH(CH554,ten_tinh,0))) | CK554: =IF(ISBLANK(CJ554),"",INDEX(mahuyen,MATCH(CONCATENATE(CI554,"-",CJ554),Loc_trung_huyen,0))) | CO554: =IF(ISBLANK(CN554),"",INDEX(matinh,MATCH(CN554,ten_tinh,0))) | CQ554: =IF(ISBLANK(CP554),"",INDEX(mahuyen,MATCH(CONCATENATE(CO554,"-",CP554),Loc_trung_huyen,0))) | CZ554: =IF(ISBLANK(CY554),"",INDEX(maquocgia,MATCH(CY554,dm_quocgia,0))) | DE554: =IF(ISBLANK(DD554),"",INDEX(mamoiquanhe,MATCH(DD554,moiquanhe,0))) | DG554: =IF(ISBLANK(DF554),"",INDEX(matinh,MATCH(DF554,ten_tinh,0))) | DI554: =IF(ISBLANK(DH554),"",INDEX(mahuyen,MATCH(CONCATENATE(DG554,"-",DH554),Loc_trung_huyen,0)))
E555: =IF(ISBLANK(D555),"",INDEX(maloaipa,MATCH(D555,loaipa,0))) | AT555: =IF(ISBLANK(AS555),"",INDEX(maquocgia,MATCH(AS555,dm_quocgia,0))) | AV555: =IF(ISBLANK(AU555),"",INDEX(madantoc,MATCH(AU555,tendantoc,0))) | AX555: {=IFERROR(INDEX(Tinh!A:A,MATCH(TRIM(AW555),Tinh!B:B,0)),"")} | AZ555: {=IFERROR(INDEX('Ngân Hàng'!B:B,MATCH(AY555,'Ngân Hàng'!C:C,0)),"")} | BD555: =IF(ISBLANK(BC555),"",INDEX(matinh,MATCH(BC555,ten_tinh,0))) | BF555: =IF(ISBLANK(BE555),"",INDEX(mahuyen,MATCH(CONCATENATE(BD555,"-",BE555),Loc_trung_huyen,0))) | BI555: =IF(ISBLANK(BH555),"",INDEX(matinh,MATCH(BH555,ten_tinh,0))) | BK555: =IF(ISBLANK(BJ555),"",INDEX(mahuyen,MATCH(CONCATENATE(BI555,"-",BJ555),Loc_trung_huyen,0))) | BN555: =IF(ISBLANK(BM555),"",INDEX(matinh,MATCH(BM555,ten_tinh,0))) | BP555: {=IF(ISBLANK(BO555),"",INDEX(mabenhvien,MATCH(BO555&BN555,tenbenhvien&matinhbenhvien,0)))} | BS555: =IF(ISBLANK(BR555),"",INDEX(matinh,MATCH(BR555,ten_tinh,0))) | BU555: =IF(ISBLANK(BT555),"",INDEX(mahuyen,MATCH(CONCATENATE(BS555,"-",BT555),Loc_trung_huyen,0))) | CI555: =IF(ISBLANK(CH555),"",INDEX(matinh,MATCH(CH555,ten_tinh,0))) | CK555: =IF(ISBLANK(CJ555),"",INDEX(mahuyen,MATCH(CONCATENATE(CI555,"-",CJ555),Loc_trung_huyen,0))) | CO555: =IF(ISBLANK(CN555),"",INDEX(matinh,MATCH(CN555,ten_tinh,0))) | CQ555: =IF(ISBLANK(CP555),"",INDEX(mahuyen,MATCH(CONCATENATE(CO555,"-",CP555),Loc_trung_huyen,0))) | DE555: =IF(ISBLANK(DD555),"",INDEX(mamoiquanhe,MATCH(DD555,moiquanhe,0))) | DG555: =IF(ISBLANK(DF555),"",INDEX(matinh,MATCH(DF555,ten_tinh,0))) | DI555: =IF(ISBLANK(DH555),"",INDEX(mahuyen,MATCH(CONCATENATE(DG555,"-",DH555),Loc_trung_huyen,0)))
E556: =IF(ISBLANK(D556),"",INDEX(maloaipa,MATCH(D556,loaipa,0))) | AT556: =IF(ISBLANK(AS556),"",INDEX(maquocgia,MATCH(AS556,dm_quocgia,0))) | AV556: =IF(ISBLANK(AU556),"",INDEX(madantoc,MATCH(AU556,tendantoc,0))) | AX556: {=IFERROR(INDEX(Tinh!A:A,MATCH(TRIM(AW556),Tinh!B:B,0)),"")} | AZ556: {=IFERROR(INDEX('Ngân Hàng'!B:B,MATCH(AY556,'Ngân Hàng'!C:C,0)),"")} | BD556: =IF(ISBLANK(BC556),"",INDEX(matinh,MATCH(BC556,ten_tinh,0))) | BF556: =IF(ISBLANK(BE556),"",INDEX(mahuyen,MATCH(CONCATENATE(BD556,"-",BE556),Loc_trung_huyen,0))) | BI556: =IF(ISBLANK(BH556),"",INDEX(matinh,MATCH(BH556,ten_tinh,0))) | BK556: =IF(ISBLANK(BJ556),"",INDEX(mahuyen,MATCH(CONCATENATE(BI556,"-",BJ556),Loc_trung_huyen,0))) | BN556: =IF(ISBLANK(BM556),"",INDEX(matinh,MATCH(BM556,ten_tinh,0))) | BP556: {=IF(ISBLANK(BO556),"",INDEX(mabenhvien,MATCH(BO556&BN556,tenbenhvien&matinhbenhvien,0)))} | BS556: =IF(ISBLANK(BR556),"",INDEX(matinh,MATCH(BR556,ten_tinh,0))) | BU556: =IF(ISBLANK(BT556),"",INDEX(mahuyen,MATCH(CONCATENATE(BS556,"-",BT556),Loc_trung_huyen,0))) | CI556: =IF(ISBLANK(CH556),"",INDEX(matinh,MATCH(CH556,ten_tinh,0))) | CK556: =IF(ISBLANK(CJ556),"",INDEX(mahuyen,MATCH(CONCATENATE(CI556,"-",CJ556),Loc_trung_huyen,0))) | CO556: =IF(ISBLANK(CN556),"",INDEX(matinh,MATCH(CN556,ten_tinh,0))) | CQ556: =IF(ISBLANK(CP556),"",INDEX(mahuyen,MATCH(CONCATENATE(CO556,"-",CP556),Loc_trung_huyen,0))) | DE556: =IF(ISBLANK(DD556),"",INDEX(mamoiquanhe,MATCH(DD556,moiquanhe,0))) | DG556: =IF(ISBLANK(DF556),"",INDEX(matinh,MATCH(DF556,ten_tinh,0))) | DI556: =IF(ISBLANK(DH556),"",INDEX(mahuyen,MATCH(CONCATENATE(DG556,"-",DH556),Loc_trung_huyen,0)))
